Workbook
Name DoubleCount: 'Envizi mapping notes'!$A$23:$A$36

Sheet Summary
B2: Forecast Buffer | C2: 0.05
B4: Country | C4: Australia | H4: Country | I4: New Zealand
B6: Row Labels | C6: Count of Connection ID | D6: Sum of FY26 Budget | E6: Sum of FY27 Budget | F6: Sum of FY28 Budget | H6: Row Labels | I6: Count of Connection ID | J6: Sum of FY26 Budget | K6: Sum of FY27 Budget | L6: Sum of FY28 Budget
B7: Electricity | H7: Electricity
B8: AU Large Electricity | H8: NZ NTOU Electricity
B9: ACT | C9: 1 | D9: 250500 | E9: 194100 | F9: 192500 | H9: North Island | I9: 96 | J9: 894400 | K9: 1046200 | L9: 1046200
B10: NSW | C10: 36 | D10: 8697700 | E10: 7443200 | F10: 7402300 | H10: South Island | I10: 36 | J10: 367000 | K10: 405300 | L10: 405300
B11: NT | C11: 3 | D11: 718000 | E11: 822300 | F11: 822300 | H11: NZ NTOU Electricity Total | I11: 132 | J11: 1261400 | K11: 1451500 | L11: 1451500
B12: QLD | C12: 17 | D12: 4434000 | E12: 4031200 | F12: 4061800 | H12: NZ TOU Electricity
B13: SA | C13: 4 | D13: 556200 | E13: 452900 | F13: 454900 | H13: North Island | I13: 17 | J13: 2353000 | K13: 1928800 | L13: 1928800
B14: TAS | C14: 3 | D14: 402900 | E14: 321700 | F14: 321300 | H14: South Island | I14: 9 | J14: 705700 | K14: 631000 | L14: 631000
B15: VIC | C15: 10 | D15: 1082100 | E15: 1056600 | F15: 1061500 | H15: NZ TOU Electricity Total | I15: 26 | J15: 3058700 | K15: 2559800 | L15: 2559800
B16: WA | C16: 7 | D16: 2045700 | E16: 1937600 | F16: 1937600 | H16: Electricity Total | I16: 158 | J16: 4320100 | K16: 4011300 | L16: 4011300
B17: AU Large Electricity Total | C17: 81 | D17: 18187100 | E17: 16259600 | F17: 16254200 | H17: Natural Gas
B18: AU Small Energy | H18: NZ NTOU Natural Gas
B19: NSW | C19: 11 | D19: 198000 | E19: 150000 | F19: 150000 | H19: North Island | I19: 12 | J19: 17100 | K19: 17900 | L19: 17900
B20: QLD | C20: 5 | D20: 62400 | E20: 61500 | F20: 61500 | H20: NZ NTOU Natural Gas Total | I20: 12 | J20: 17100 | K20: 17900 | L20: 17900
B21: SA | C21: 10 | D21: 74600 | E21: 66500 | F21: 66500 | H21: NZ TOU Natural Gas
B22: VIC | C22: 24 | D22: 152500 | E22: 117100 | F22: 117100 | H22: North Island | I22: 8 | J22: 5325500 | K22: 4602800 | L22: 4602800
B23: AU Small Energy Total | C23: 50 | D23: 487500 | E23: 395100 | F23: 395100 | H23: NZ TOU Natural Gas Total | I23: 8 | J23: 5325500 | K23: 4602800 | L23: 4602800
B24: Electricity Total | C24: 131 | D24: 18674600 | E24: 16654700 | F24: 16649300 | H24: Natural Gas Total | I24: 20 | J24: 5342600 | K24: 4620700 | L24: 4620700
B25: Natural Gas | H25: Grand Total | I25: 178 | J25: 9662700 | K25: 8632000 | L25: 8632000
B26: AU Large Natural Gas
B27: ACT | C27: 1 | D27: 1015100 | E27: 982100 | F27: 975800
B28: NSW | C28: 4 | D28: 3310300 | E28: 3173000 | F28: 3188000
B29: SA | C29: 2 | D29: 2820800 | E29: 2750300 | F29: 2797600
B30: TAS | C30: 1 | D30: 283000 | E30: 283000 | F30: 283000
B31: VIC | C31: 3 | D31: 3976100 | E31: 3553100 | F31: 3559400
B32: WA | C32: 4 | D32: 985200 | E32: 959200 | F32: 959200
B33: AU Large Natural Gas Total | C33: 15 | D33: 12390500 | E33: 11700700 | F33: 11763000
B34: AU Small Energy
B35: NSW | C35: 11 | D35: 6500 | E35: 5500 | F35: 5500
B36: QLD | C36: 4 | D36: 67700 | E36: 69700 | F36: 69700
B37: SA | C37: 1 | D37: 22800 | E37: 26500 | F37: 26500
B38: VIC | C38: 1 | D38: 500 | E38: 500 | F38: 500
B39: AU Small Energy Total | C39: 17 | D39: 97500 | E39: 102200 | F39: 102200
B40: Natural Gas Total | C40: 32 | D40: 12488000 | E40: 11802900 | F40: 11865200
B41: Grand Total | C41: 163 | D41: 31162600 | E41: 28457600 | F41: 28514500

Sheet Site Register
A1: Downer Energy Portfolio – Consolidated Site Register
A2: Connection ID | B2: Commodity | C2: Country | D2: State / Region | E2: Portfolio Group | F2: Site Name | G2: Address | H2: Entity | I2: Business Unit | J2: Units | K2: Annual Consumption | L2: Retailer at Tender | M2: Contracted Retailer | N2: New Contract Start | O2: New Contract End | P2: Term | Q2: FY26 Budget | R2: FY27 Budget | S2: FY28 Budget | T2: Budget Status | U2: Notes | V2: Envizi Account Number | W2: Envizi Account Style | X2: Envizi Data Type | Y2: Envizi Supplier | Z2: Envizi Location | AA2: Envizi Location Ref | AB2: Account Status | AC2: Match Basis | AD2: Other Envizi accounts on this ID | AE2: Certificate / virtual meter account
A3: 5265773931 | B3: Natural Gas | C3: Australia | D3: ACT | E3: AU Large Natural Gas | G3: 7 Tralee Street, Hume ACT 2620 | H3: DOWNER EDI WORKS PTY LTD (ABN: 66 008 709 608) | I3: T&I | J3: GJ | K3: 30729.026 | L3: Origin | M3: Origin | N3: 46388 | O3: 47483 | P3: 36 months | Q3: {=IFERROR(ROUNDUP(_xlfn.XLOOKUP(A3,'Budget FY26-28'!A:A,'Budget FY26-28'!M:O)*(1+Summary!$C$2), -2), "")} | R3: 982100 | S3: 975800 | T3: Ready | V3: 50002801028_5265773931 | W3: Natural Gas - PDF Parsing | X3: Natural Gas [GJ] | Y3: Origin | Z3: Asphalt Prod - Hume (101) | AA3: 101 | AB3: Active | AC3: Connection ID is the account number suffix | AD3: 1963107867_5265773931; 50000353781_5265773931 | AE3: LGCS_7001184714 (at this location, different ID) - historical
A4: 5242077399 | B4: Natural Gas | C4: Australia | D4: NSW | E4: AU Large Natural Gas | G4: ICC Darling Drive, Darling Harbour NSW 2000 | H4: SPOTLESS FACILITY SERVICES PTY LTD (ABN: 83 072 293 880) | I4: SICS | J4: GJ | K4: 19847.411 | L4: ShellEnergyAU | M4: Shell | N4: 46023 | O4: 46752 | P4: 12 months | Q4: {=IFERROR(ROUNDUP(_xlfn.XLOOKUP(A4,'Budget FY26-28'!A:A,'Budget FY26-28'!M:O)*(1+Summary!$C$2), -2), "")} | R4: 580400 | S4: 589800 | T4: Ready | V4: 2100433_5242077399 | W4: Natural Gas - PDF Parsing | X4: Natural Gas [GJ] | Y4: ShellEnergyAU | Z4: PPP - SICEEP | AA4: 9077 | AB4: Active | AC4: Connection ID is the account number suffix | AD4: 50000102373_5242077399 | AE4: LGCS_4103927804 (at this location, different ID) - historical · LGCS_4103927806 (at this location, different ID) - historical · LGCS_4103927808 (at this location, different ID) - historical · LGCS_4103927809 (at this location, different ID) - historical
A5: 5247064745 | B5: Natural Gas | C5: Australia | D5: NSW | E5: AU Large Natural Gas | G5: 460 Main Road, Glendale NSW 2285 | H5: DOWNER EDI RAIL PTY LTD (ABN: 92 000 002 031) | I5: RAIL | J5: GJ | K5: 2500 | L5: Origin | M5: Origin | N5: 46388 | O5: 47483 | P5: 36 months | Q5: {=IFERROR(ROUNDUP(_xlfn.XLOOKUP(A5,'Budget FY26-28'!A:A,'Budget FY26-28'!M:O)*(1+Summary!$C$2), -2), "")} | R5: 64000 | S5: 65700 | T5: Ready | V5: 50002958793_5247064745 | W5: Natural Gas - PDF Parsing | X5: Natural Gas [GJ] | Y5: Origin | Z5: Cardiff - Rail | AA5: 3004 | AB5: Active | AC5: Connection ID is the account number suffix | AD5: 51632065_5247064745; Tenant 51632065_5247064745; 1109120_5247064745; Tenant 1109120_5247064745; 7733066771_5247064745; 9248380435_5247064745; Tenant 7733066771_5247064745; Tenant 9248380435_5247064745; A-DF77364D_5247064745; Tenant A-DF77364D_5247064745; Tenant Apportionment 50002958793_5247064745
A6: 5248353654 | B6: Natural Gas | C6: Australia | D6: NSW | E6: AU Large Natural Gas | G6: 9 Devon St, Rosehill NSW 2142 | H6: DOWNER EDI SERVICES PTY LTD (ABN: 71 137 732 042) | I6: T&I | J6: GJ | K6: 108015.37 | L6: ShellEnergyAU | M6: Shell | N6: 46023 | O6: 46752 | P6: 12 months | Q6: {=IFERROR(ROUNDUP(_xlfn.XLOOKUP(A6,'Budget FY26-28'!A:A,'Budget FY26-28'!M:O)*(1+Summary!$C$2), -2), "")} | R6: 2465100 | S6: 2532500 | T6: Ready | V6: 2100432_5248353654 | W6: Natural Gas - PDF Parsing | X6: Natural Gas [GJ] | Y6: ShellEnergyAU | Z6: Asphalt Prod - Rosehill (163) | AA6: 163 | AB6: Active | AC6: Connection ID is the account number suffix | AD6: 50002719045_5248353654 | AE6: LGCS_4311396021 (at this location, different ID) - historical · LGCS_4311396022 (at this location, different ID) - historical
A7: 5265761108 | B7: Natural Gas | C7: Australia | D7: NSW | E7: AU Large Natural Gas | G7: 5800 Kings Highway, Bungendore NSW 2621 | H7: SPOTLESS FACILITY SERVICES PTY LTD (ABN: 83 072 293 880) | I7: SICS | J7: GJ | K7: 1300 | L7: Origin | M7: Origin | N7: 46388 | O7: 46752 | P7: 12 months | Q7: {=IFERROR(ROUNDUP(_xlfn.XLOOKUP(A7,'Budget FY26-28'!A:A,'Budget FY26-28'!M:O)*(1+Summary!$C$2), -2), "")} | R7: 63500 | S7: 0 | T7: Ready | V7: 50002959329_5265761108 | W7: Natural Gas - PDF Parsing | X7: Natural Gas [GJ] | Y7: Origin | Z7: PPP - HQJOC (ACT) | AA7: 9092 | AB7: Active | AC7: Connection ID is the account number suffix | AD7: 701221629213_5265761108; A-D62CBEED_5265761108
A8: 5510072233 | B8: Natural Gas | C8: Australia | D8: SA | E8: AU Large Natural Gas | G8: 557 Grand Junction Road, Wingfield SA 5013 | H8: DOWNER EDI SERVICES PTY LTD (ABN: 71 137 732 042) | I8: T&I | J8: GJ | K8: 92565.36 | L8: ShellEnergyAU | M8: Shell | N8: 46023 | O8: 46752 | P8: 12 months | Q8: {=IFERROR(ROUNDUP(_xlfn.XLOOKUP(A8,'Budget FY26-28'!A:A,'Budget FY26-28'!M:O)*(1+Summary!$C$2), -2), "")} | R8: 2403600 | S8: 2449300 | T8: Ready | V8: 2100431_5510072233 | W8: Natural Gas - PDF Parsing | X8: Natural Gas [GJ] | Y8: ShellEnergyAU | Z8: Asphalt Prod - Wingfield (523) | AA8: 523 | AB8: Active | AC8: Connection ID is the account number suffix | AD8: 15005551610_5510072233 | AE8: LGCS_2002254877 (at this location, different ID) - historical
A9: 5510485000 | B9: Natural Gas | C9: Australia | D9: SA | E9: AU Large Natural Gas | G9: Wills Street, Largs Bay SA 5016 | H9: DOWNER EDI SERVICES PTY LTD (ABN: 71 137 732 042) | I9: T&I | J9: GJ | K9: 13214.104 | L9: ShellEnergyAU | M9: Shell | N9: 46023 | O9: 46752 | P9: 12 months | Q9: {=IFERROR(ROUNDUP(_xlfn.XLOOKUP(A9,'Budget FY26-28'!A:A,'Budget FY26-28'!M:O)*(1+Summary!$C$2), -2), "")} | R9: 346700 | S9: 348300 | T9: Ready | V9: 2100430_5510485000 | W9: Natural Gas - PDF Parsing | X9: Natural Gas [GJ] | Y9: ShellEnergyAU | Z9: Largs Bay | AA9: 163 | AB9: Active | AC9: Connection ID is the account number suffix | AD9: 15000948910_5510485000 | AE9: LGCS_SAAAAAB023 (at this location, different ID) - historical · LGCS_SAAAAAC481 (at this location, different ID) - historical
A10: 5762711908 | B10: Natural Gas | C10: Australia | D10: TAS | E10: AU Large Natural Gas | G10: 59 Remount Road, Mowbray TAS 7248 | H10: DOWNER EDI WORKS PTY LTD (ABN: 66 008 709 608) | I10: T&I | J10: GJ | K10: 15621.564 | L10: Solstice | M10: Solstice Energy | N10: 45658 | O10: 46387 | P10: Existing term to 31-Dec-2026 | Q10: {=IFERROR(ROUNDUP(_xlfn.XLOOKUP(A10,'Budget FY26-28'!A:A,'Budget FY26-28'!M:O)*(1+Summary!$C$2), -2), "")} | R10: 283000 | S10: 283000 | T10: FY26 secured | U10: No further term secured | V10: 2000120410_5762711908 | W10: Natural Gas - PDF Parsing | X10: Natural Gas [GJ] | Y10: SolsticeEnergy | Z10: Asphalt Prod - Mowbray (360) | AA10: 360 | AB10: Active | AC10: Connection ID is the account number suffix
A11: 5310000243 | B11: Natural Gas | C11: Australia | D11: VIC | E11: AU Large Natural Gas | G11: 18 Jersey Road, Bayswater VIC 3153 | H11: DOWNER EDI SERVICES PTY LTD (ABN: 71 137 732 042) | I11: T&I | J11: GJ | K11: 57783.717 | L11: ShellEnergyAU | M11: Shell | N11: 46023 | O11: 46752 | P11: 12 months | Q11: {=IFERROR(ROUNDUP(_xlfn.XLOOKUP(A11,'Budget FY26-28'!A:A,'Budget FY26-28'!M:O)*(1+Summary!$C$2), -2), "")} | R11: 1132200 | S11: 1134900 | T11: Ready | V11: 2100427_5310000243 | W11: Natural Gas - PDF Parsing | X11: Natural Gas [GJ] | Y11: ShellEnergyAU | Z11: Asphalt Prod - Bayswater (302) | AA11: 302 | AB11: Active | AC11: Connection ID is the account number suffix | AD11: 15000096411_5310000243 | AE11: LGCS_6305920528 (at this location, different ID) - historical
A12: 5320000943 | B12: Natural Gas | C12: Australia | D12: VIC | E12: AU Large Natural Gas | G12: Apollo Drive, Shepparton VIC 3630 | H12: DOWNER EDI SERVICES PTY LTD (ABN: 71 137 732 042) | I12: T&I | J12: GJ | K12: 23114.486 | L12: ShellEnergyAU | M12: Shell | N12: 46023 | O12: 46752 | P12: 12 months | Q12: {=IFERROR(ROUNDUP(_xlfn.XLOOKUP(A12,'Budget FY26-28'!A:A,'Budget FY26-28'!M:O)*(1+Summary!$C$2), -2), "")} | R12: 481500 | S12: 483200 | T12: Ready | V12: 2100428_5320000943 | W12: Natural Gas - PDF Parsing | X12: Natural Gas [GJ] | Y12: ShellEnergyAU | Z12: Asphalt Prod - Shepparton (308) | AA12: 308 | AB12: Active | AC12: Connection ID is the account number suffix | AD12: 15000093211_5320000943 | AE12: LGCS_VCCCSC0020 (at this location, different ID) - historical
A13: 5330662312 | B13: Natural Gas | C13: Australia | D13: VIC | E13: AU Large Natural Gas | G13: 125 Somerton Road, Somerton VIC 3062 | H13: DOWNER EDI SERVICES PTY LTD (ABN: 71 137 732 042) | I13: T&I | J13: GJ | K13: 103871.24 | L13: ShellEnergyAU | M13: Shell | N13: 46023 | O13: 46752 | P13: 12 months | Q13: {=IFERROR(ROUNDUP(_xlfn.XLOOKUP(A13,'Budget FY26-28'!A:A,'Budget FY26-28'!M:O)*(1+Summary!$C$2), -2), "")} | R13: 1939400 | S13: 1941300 | T13: Ready | V13: 2100429_5330662312 | W13: Natural Gas - PDF Parsing | X13: Natural Gas [GJ] | Y13: ShellEnergyAU | Z13: Asphalt Prod - Somerton (303) | AA13: L9.J.17032627 | AB13: Active | AC13: Connection ID is the account number suffix | AD13: 15005712110_5330662312 | AE13: LGCS_6001311036 (at this location, different ID) - historical
A14: 5600405263 | B14: Natural Gas | C14: Australia | D14: WA | E14: AU Large Natural Gas | G14: 73 Bickley Road, Beckenham WA 6107 | H14: DOWNER EDI SERVICES PTY LTD (ABN: 71 137 732 042) | I14: T&I | J14: GJ | K14: 590 | L14: Perth Energy | M14: Kleenheat | N14: 46023 | O14: 46752 | P14: To 31-Dec-2027 | Q14: {=IFERROR(ROUNDUP(_xlfn.XLOOKUP(A14,'Budget FY26-28'!A:A,'Budget FY26-28'!M:O)*(1+Summary!$C$2), -2), "")} | R14: 12000 | S14: 12000 | T14: Ready | V14: 3228711_5600405263 | W14: Natural Gas - PDF Parsing | X14: Natural Gas [GJ] | Y14: Kleenheat | Z14: Cannington Emulsion Plant | AA14: 39 | AB14: Active | AC14: Connection ID is the account number suffix | AD14: 129001507_5600405263; 805045016_5600405263; 3176624_5600405263; 605461_5600405263; 608258_5600405263
A15: 5600436929 | B15: Natural Gas | C15: Australia | D15: WA | E15: AU Large Natural Gas | G15: 95 Cockram Road, Martin WA 6110 | H15: DOWNER EDI SERVICES PTY LTD (ABN: 71 137 732 042) | I15: T&I | J15: GJ | K15: 23242.137 | L15: Perth Energy | M15: Kleenheat | N15: 46023 | O15: 46752 | P15: To 31-Dec-2027 | Q15: {=IFERROR(ROUNDUP(_xlfn.XLOOKUP(A15,'Budget FY26-28'!A:A,'Budget FY26-28'!M:O)*(1+Summary!$C$2), -2), "")} | R15: 326700 | S15: 326700 | T15: Ready | V15: 3176624_5600436929 | W15: Natural Gas - PDF Parsing | X15: Natural Gas [GJ] | Y15: Kleenheat | Z15: Asphalt Prod - Gosnells (621) | AA15: 621 | AB15: Active | AC15: Connection ID is the account number suffix | AD15: 11804846_5600436929; 80005968_5600436929; 606714_5600436929
A16: 5600604830 | B16: Natural Gas | C16: Australia | D16: WA | E16: AU Large Natural Gas | G16: Unit 1, 5 Mounts Bay Road, Perth WA 6000 | H16: SPOTLESS FACILITY SERVICES PTY LTD (ABN: 83 072 293 880) | I16: SICS | J16: GJ | K16: 9471.6073 | L16: Perth Energy | M16: Kleenheat | N16: 46023 | O16: 46752 | P16: To 31-Dec-2027 | Q16: {=IFERROR(ROUNDUP(_xlfn.XLOOKUP(A16,'Budget FY26-28'!A:A,'Budget FY26-28'!M:O)*(1+Summary!$C$2), -2), "")} | R16: 156500 | S16: 156500 | T16: Ready | V16: 3176620_5600604830 | W16: Natural Gas - PDF Parsing | X16: Natural Gas [GJ] | Y16: Kleenheat | Z16: LSE - Perth Convention & Exhibition Centre (WA) | AA16: 9068 | AB16: Active | AC16: Connection ID is the account number suffix | AD16: 11804879_5600604830; 80012725_5600604830; 606716_5600604830
A17: 5600945901 | B17: Natural Gas | C17: Australia | D17: WA | E17: AU Large Natural Gas | G17: Lot 106 Corner Hoyle & Conway Road, Hope Valley WA 6165 | H17: DOWNER EDI SERVICES PTY LTD (ABN: 71 137 732 042) | I17: T&I | J17: GJ | K17: 34066.928 | L17: Perth Energy | M17: Kleenheat | N17: 46023 | O17: 46752 | P17: To 31-Dec-2027 | Q17: {=IFERROR(ROUNDUP(_xlfn.XLOOKUP(A17,'Budget FY26-28'!A:A,'Budget FY26-28'!M:O)*(1+Summary!$C$2), -2), "")} | R17: 464000 | S17: 464000 | T17: Ready | V17: 3228713_5600945901 | W17: Natural Gas - PDF Parsing | X17: Natural Gas [GJ] | Y17: Kleenheat | Z17: Asphalt Prod - Hope Valley (628) | AA17: 628 | AB17: Active | AC17: Connection ID is the account number suffix | AD17: 11804853_5600945901; 80010413_5600945901; 3176624_5600945901; 606715_5600945901
A18: 3053253239 | B18: Electricity | C18: Australia | D18: QLD | E18: AU Large Electricity | F18: Torbanlea | G18: TRAIN FACILTY BRUCE HWY TORBANLEA 35 QLD 4662 | H18: DOWNER EDI SERVICES PTY LTD (ABN: 71 137 732 042) | I18: RAIL | J18: kWh | K18: 6208798 | L18: CS Energy | M18: Engie | N18: 46204 | O18: 46934 | P18: 24 months | Q18: {=IFERROR(ROUNDUP(_xlfn.XLOOKUP(A18,'Budget FY26-28'!A:A,'Budget FY26-28'!M:O)*(1+Summary!$C$2), -2), "")} | R18: 1165400 | S18: 1174900 | T18: Ready | V18: 900018201_3053253239 | W18: Electricity Small Market | X18: Electricity [kWh] | Y18: EngieAU | Z18: Torbanlea - QTMP | AB18: Active | AC18: Connection ID is the account number suffix | AD18: 1003571_3053253239; 5000021_3053253239 | AE18: 900018201_3053253239_CERTS (to create)
A19: 6305885252 | B19: Electricity | C19: Australia | D19: VIC | E19: AU Large Electricity | G19: 81 MCMILLAN STREET LUCKNOW VIC 3875 LUCKNOW VIC | H19: DOWNER EDI SERVICES PTY LTD (ABN: 71 137 732 042) | J19: kWh | K19: 201844 | L19: Origin | M19: Engie | N19: 46204 | O19: 46934 | P19: 24 months | Q19: {=IFERROR(ROUNDUP(_xlfn.XLOOKUP(A19,'Budget FY26-28'!A:A,'Budget FY26-28'!M:O)*(1+Summary!$C$2), -2), "")} | R19: 57800 | S19: 58100 | T19: Ready | V19: 900018218_6305885252 | W19: Electricity Small Market | X19: Electricity [kWh] | Y19: EngieAU | Z19: Gippsland Asphalt - Bairnsdale | AA19: 103.1 | AB19: Active | AC19: Connection ID is the account number suffix | AD19: 900018218_6305885252_CERTS; 50002976775_6305885252 | AE19: 900018218_6305885252_CERTS (live)
A20: 4001050448 | B20: Electricity | C20: Australia | D20: NSW | E20: AU Small Energy | F20: Roads - Forbes | G20: SAM STREET FORBES NSW 2871 | H20: DOWNER EDI WORKS PTY LTD (ABN: 66 008 709 608) | I20: ROAD SERVICES | J20: kWh | K20: 28354 | L20: Origin | M20: Origin | N20: 46204 | O20: 46934 | P20: 24 months | Q20: {=IFERROR(ROUNDUP(_xlfn.XLOOKUP(A20,'Budget FY26-28'!A:A,'Budget FY26-28'!M:O)*(1+Summary!$C$2), -2), "")} | R20: 9400 | S20: 9400 | T20: Ready | V20: A-5F3C0784_4001050448 | W20: Electricity Small Market | X20: Electricity [kWh] | Y20: Origin | Z20: Forbes | AA20: 116 | AB20: Active | AC20: Connection ID is the account number suffix | AD20: 200021563685_4001050448
A21: 4001128707 | B21: Electricity | C21: Australia | D21: NSW | E21: AU Small Energy | F21: Roads - Westdale (Tamworth) | G21: 15 ARMSTRONG STREET WESTDALE NSW 2340 | H21: DOWNER EDI WORKS PTY LTD (ABN: 66 008 709 608) | I21: ROAD SERVICES | J21: kWh | K21: 0 | L21: Origin | M21: Origin | N21: 46204 | O21: 46934 | P21: 24 months | Q21: {=IFERROR(ROUNDUP(_xlfn.XLOOKUP(A21,'Budget FY26-28'!A:A,'Budget FY26-28'!M:O)*(1+Summary!$C$2), -2), "")} | R21: 0 | S21: 0 | T21: Review required | U21: No consumption reported | V21: A-2A4343BB_4001128707 | W21: Electricity Small Market | X21: Electricity [kWh] | Y21: Origin | Z21: Tamworth | AA21: 170937 | AB21: Active | AC21: Connection ID is the account number suffix | AD21: 200021563628_4001128707 | AE21: LGCS_4001158058 (at this location, different ID) - historical
A22: 4001174306 | B22: Electricity | C22: Australia | D22: NSW | E22: AU Small Energy | F22: Roads - Westdale (Tamworth) | G22: 23 ARMSTRONG STREET WESTDALE NSW 2340 | H22: DOWNER EDI WORKS PTY LTD (ABN: 66 008 709 608) | I22: ROAD SERVICES | J22: kWh | K22: 254401 | L22: Origin | M22: Origin | N22: 46204 | O22: 46934 | P22: 24 months | Q22: {=IFERROR(ROUNDUP(_xlfn.XLOOKUP(A22,'Budget FY26-28'!A:A,'Budget FY26-28'!M:O)*(1+Summary!$C$2), -2), "")} | R22: 74700 | S22: 74700 | T22: Ready | V22: A-0B2330E0_4001174306 | W22: Electricity Small Market | X22: Electricity [kWh] | Y22: Origin | Z22: Tamworth | AA22: 170937 | AB22: Active | AC22: Connection ID is the account number suffix | AE22: LGCS_4001158058 (at this location, different ID) - historical
A23: 4001231357 | B23: Electricity | C23: Australia | D23: NSW | E23: AU Small Energy | F23: Surfacing Lismore | G23: 64 Lancaster Drive Goonellabah NSW 2480 | H23: DOWNER EDI WORKS PTY LTD (ABN: 66 008 709 608) | I23: Roads | J23: kWh | K23: 30776 | L23: Origin | M23: Origin | N23: 46204 | O23: 46934 | P23: 24 months | Q23: {=IFERROR(ROUNDUP(_xlfn.XLOOKUP(A23,'Budget FY26-28'!A:A,'Budget FY26-28'!M:O)*(1+Summary!$C$2), -2), "")} | R23: 13200 | S23: 13200 | T23: Ready | V23: A-12B8B627_4001231357 | W23: Electricity Small Market | X23: Electricity [kWh] | Y23: Origin | Z23: RPQ NSW Lismore Depot | AA23: 170426 | AB23: Active | AC23: Connection ID is the account number suffix
A24: 4001277522 | B24: Electricity | C24: Australia | D24: NSW | E24: AU Small Energy | F24: RPQ South Grafton | G24: Lot 42 Tyson St, , South Grafton NSW 2460 | H24: RPQ PTY LTD (ABN: 53 010 760 826) | I24: RPQ | J24: kWh | K24: 9299 | L24: Origin | M24: Origin | N24: 46204 | O24: 46934 | P24: 24 months | Q24: {=IFERROR(ROUNDUP(_xlfn.XLOOKUP(A24,'Budget FY26-28'!A:A,'Budget FY26-28'!M:O)*(1+Summary!$C$2), -2), "")} | R24: 3800 | S24: 3800 | T24: Ready | V24: A-480CA3BE_4001277522 | W24: Electricity Small Market | X24: Electricity [kWh] | Y24: Origin | Z24: RPQ NSW South Grafton | AA24: L9.J.171215 | AB24: Active | AC24: Connection ID is the account number suffix | AD24: A-B500CC5F_4001277522
A25: 4103512903 | B25: Electricity | C25: Australia | D25: NSW | E25: AU Small Energy | F25: Rail Hornsby | G25: 29 Leighton Place Hornsby NSW 2077 | H25: DOWNER EDI RAIL PTY LTD (ABN: 92 000 002 031) | I25: Rail | J25: kWh | K25: 15039 | L25: AGL | M25: Origin | N25: 46204 | O25: 46934 | P25: 24 months | Q25: {=IFERROR(ROUNDUP(_xlfn.XLOOKUP(A25,'Budget FY26-28'!A:A,'Budget FY26-28'!M:O)*(1+Summary!$C$2), -2), "")} | R25: 4100 | S25: 4100 | T25: Ready | V25: 7093364037_4103512903 | W25: Electricity Small Market | X25: Electricity [kWh] | Y25: AGL | Z25: WTP Mobile Tech Hornsby | AA25: 3025 | AB25: Active | AC25: Connection ID is the account number suffix
A26: 4104037195 | B26: Electricity | C26: Australia | D26: NSW | E26: AU Small Energy | F26: Whole of Government -Riverwood | G26: 5-7 Littleton St Riverwood NSW 2190 | H26: SPOTLESS FACILITY SERVICES PTY LTD (ABN: 83 072 293 880) | I26: Spotless | J26: kWh | K26: 2938 | L26: Origin | M26: Origin | N26: 46204 | O26: 46934 | P26: 24 months | Q26: {=IFERROR(ROUNDUP(_xlfn.XLOOKUP(A26,'Budget FY26-28'!A:A,'Budget FY26-28'!M:O)*(1+Summary!$C$2), -2), "")} | R26: 1500 | S26: 1500 | T26: Ready | V26: A-EE80EEC5_4104037195 | W26: Electricity Small Market | X26: Electricity [kWh] | Y26: Origin | Z26: Spotless FM - Riverwood office | AB26: Active | AC26: Connection ID is the account number suffix | AD26: A-67BE8F15_4104037195
A27: 4204234430 | B27: Electricity | C27: Australia | D27: NSW | E27: AU Small Energy | F27: Roads - Narrandera | G27: 1 DRISCOLL DRIVE NARRANDERA NSW 2700 | H27: DOWNER EDI WORKS PTY LTD (ABN: 66 008 709 608) | I27: ROAD SERVICES | J27: kWh | K27: 16709 | L27: Origin | M27: Origin | N27: 46204 | O27: 46934 | P27: 24 months | Q27: {=IFERROR(ROUNDUP(_xlfn.XLOOKUP(A27,'Budget FY26-28'!A:A,'Budget FY26-28'!M:O)*(1+Summary!$C$2), -2), "")} | R27: 6600 | S27: 6600 | T27: Ready | V27: A-39C3EA08_4204234430 | W27: Electricity Small Market | X27: Electricity [kWh] | Y27: Origin | Z27: Asphalt Prod - Narrandera (113) | AA27: 113 | AB27: Active | AC27: Connection ID is the account number suffix | AD27: 5868854420_4204234430; 200021563602_4204234430
A28: 4310027807 | B28: Electricity | C28: Australia | D28: NSW | E28: AU Small Energy | F28: Skilltech - Rydalmere | G28: U S 16 SOUTH ST RYDALMERE NSW 2116 | H28: SKILLTECH CONSULTING SERVICES PTY. LTD. (ABN: 14 007 162 647) | I28: Spotless | J28: kWh | K28: 65379 | L28: EnergyAustralia | M28: Origin | N28: 46204 | O28: 46934 | P28: 24 months | Q28: {=IFERROR(ROUNDUP(_xlfn.XLOOKUP(A28,'Budget FY26-28'!A:A,'Budget FY26-28'!M:O)*(1+Summary!$C$2), -2), "")} | R28: 16800 | S28: 16800 | T28: Ready | V28: 4735468390_4310027807 | W28: Electricity Small Market | X28: Electricity [kWh] | Y28: EnergyAustralia | Z28: Skilltech - Rydalmere | AA28: L9.S.13000871 | AB28: Active | AC28: Connection ID is the account number suffix | AD28: 200012634040_4310027807
A29: 4311422527 | B29: Electricity | C29: Australia | D29: NSW | E29: AU Small Energy | F29: 5 Edney Lane | G29: Unit 1, 5 Edney Lane Spring Hill, NSW 2500 | H29: DOWNER EDI SERVICES PTY LTD (ABN: 71 137 732 042) | I29: Downer EDI Services Pty | J29: kWh | K29: 33060 | L29: Origin | M29: Origin | N29: 46204 | O29: 46934 | P29: 24 months | Q29: {=IFERROR(ROUNDUP(_xlfn.XLOOKUP(A29,'Budget FY26-28'!A:A,'Budget FY26-28'!M:O)*(1+Summary!$C$2), -2), "")} | R29: 8900 | S29: 8900 | T29: Ready | V29: A-1C180A27_4311422527 | W29: Electricity Small Market | X29: Electricity [kWh] | Y29: Origin | Z29: LAHC NSW - Springhill | AA29: L9.S.3174.45002371 | AB29: Active | AC29: Connection ID is the account number suffix
A30: 4407159044 | B30: Electricity | C30: Australia | D30: NSW | E30: AU Small Energy | F30: RPQ -Chinderah - NSW Spray Seal | G30: 24A Ozone St Chinderah NSW 2487 | H30: RPQ PTY LTD (ABN: 53 010 760 826) | I30: ROAD SERVICES | J30: kWh | K30: 33872 | L30: Origin | M30: Origin | N30: 46204 | O30: 46934 | P30: 24 months | Q30: {=IFERROR(ROUNDUP(_xlfn.XLOOKUP(A30,'Budget FY26-28'!A:A,'Budget FY26-28'!M:O)*(1+Summary!$C$2), -2), "")} | R30: 11000 | S30: 11000 | T30: Ready | V30: A-7098FD44_4407159044 | W30: Electricity Small Market | X30: Electricity [kWh] | Y30: Origin | Z30: RPQ NSW Chinderah | AA30: L9.J.171210 | AB30: Active | AC30: Connection ID is the account number suffix | AD30: 200051085393_4407159044; A-4005C5DE_4407159044 | AE30: LGCS_4407159054 (at this location, different ID) - historical
A31: 3038502933 | B31: Electricity | C31: Australia | D31: QLD | E31: AU Small Energy | F31: Engineering Power Gladstone | G31: 7 ROOKSBY ST GLADSTONE CENTRAL QLD 4680 | H31: DOWNER EDI ENGINEERING POWER PTY LTD (ABN: 53 000 983 700) | J31: kWh | K31: 38380 | L31: Ergon | M31: Origin | N31: 46204 | O31: 46934 | P31: 24 months | Q31: {=IFERROR(ROUNDUP(_xlfn.XLOOKUP(A31,'Budget FY26-28'!A:A,'Budget FY26-28'!M:O)*(1+Summary!$C$2), -2), "")} | R31: 11800 | S31: 11800 | T31: Ready | V31: A-18650A37_3038502933 | W31: Electricity Small Market | X31: Electricity [kWh] | Y31: Ergon | Z31: Rooksby St, Gladstone | AA31: ASV-363.376.302.420 | AB31: Active | AC31: Connection ID is the account number suffix | AD31: 43183239_3038502933
A32: 3039040879 | B32: Electricity | C32: Australia | D32: QLD | E32: AU Small Energy | F32: Engineering Power - Gladstone | G32: LOT 145 ROOKSBY ST GLADSTONE CENTRAL QLD 4680 | H32: DOWNER EDI ENGINEERING POWER PTY LTD (ABN: 53 000 983 700) | I32: ENGINEERING POWER | J32: kWh | K32: 70195 | L32: Ergon | M32: Origin | N32: 46204 | O32: 46934 | P32: 24 months | Q32: {=IFERROR(ROUNDUP(_xlfn.XLOOKUP(A32,'Budget FY26-28'!A:A,'Budget FY26-28'!M:O)*(1+Summary!$C$2), -2), "")} | R32: 20900 | S32: 20900 | T32: Ready | V32: A-3B52C8FB_3039040879 | W32: Electricity Small Market | X32: Electricity [kWh] | Y32: Ergon | Z32: Rooksby St, Gladstone | AA32: ASV-363.376.302.420 | AB32: Active | AC32: Connection ID is the account number suffix | AD32: 41144911_3039040879
A33: 3041781236 | B33: Electricity | C33: Australia | D33: QLD | E33: AU Small Energy | F33: Rail - Maryborough | G33: 3 Ellena Street MARYBOROUGH QLD 4650 | H33: DOWNER EDI RAIL PTY LTD (ABN: 92 000 002 031) | I33: ROLLING STOCK | J33: kWh | K33: 53331 | L33: Ergon | M33: Origin | N33: 46204 | O33: 46934 | P33: 24 months | Q33: {=IFERROR(ROUNDUP(_xlfn.XLOOKUP(A33,'Budget FY26-28'!A:A,'Budget FY26-28'!M:O)*(1+Summary!$C$2), -2), "")} | R33: 16100 | S33: 16100 | T33: Ready | V33: A-011B63B4_3041781236 | W33: Electricity Small Market | X33: Electricity [kWh] | Y33: Ergon | Z33: Maryborough | AA33: 3011 | AB33: Active | AC33: Connection ID is the account number suffix | AD33: 7101034937_3041781236; 7029136236_3041781236 | AE33: LGCS_QGGG000010 (at this location, different ID) - historical · LGCS_QGGG000320 (at this location, different ID) - historical
A34: QB07736452 | B34: Electricity | C34: Australia | D34: QLD | E34: AU Small Energy | F34: Utilities - Kunda Park | G34: 32 PAGE STREET KUNDA PARK QLD 4556 | H34: DOWNER EDI SERVICES PTY LTD (ABN: 71 137 732 042) | I34: Utilities | J34: kWh | K34: 24596 | L34: AGL | M34: Origin | N34: 46204 | O34: 46934 | P34: 24 months | Q34: {=IFERROR(ROUNDUP(_xlfn.XLOOKUP(A34,'Budget FY26-28'!A:A,'Budget FY26-28'!M:O)*(1+Summary!$C$2), -2), "")} | R34: 8100 | S34: 8100 | T34: Ready | V34: 7099513421_QB07736452 | W34: Electricity Small Market | X34: Electricity [kWh] | Y34: AGL | Z34: Kunda Park | AA34: 10920046 | AB34: Active | AC34: Connection ID is the account number suffix | AD34: 400030619011_QB07736452
A35: QB13869604 | B35: Electricity | C35: Australia | D35: QLD | E35: AU Small Energy | F35: UAM Office - Molendinar | G35: Unit 2, 24 Export Drive Molendinar QLD 4214 | H35: Utilities Asset Management Pty Ltd (ABN: TBC) | I35: SPOTLESS | J35: kWh | K35: 16289 | L35: AGL | M35: Origin | N35: 46204 | O35: 46934 | P35: 24 months | Q35: {=IFERROR(ROUNDUP(_xlfn.XLOOKUP(A35,'Budget FY26-28'!A:A,'Budget FY26-28'!M:O)*(1+Summary!$C$2), -2), "")} | R35: 4600 | S35: 4600 | T35: Ready | V35: 7101031974_QB13869604 | W35: Electricity Small Market | X35: Electricity [kWh] | Y35: AGL | Z35: AE Smith - Molendinar | AA35: 9126 | AB35: Active | AC35: Connection ID is the account number suffix | AD35: 7051765779_QB13869604
A36: 2001130961 | B36: Electricity | C36: Australia | D36: SA | E36: AU Small Energy | F36: Utilities - Gepps Cross | G36: 535 PROSPECT ROAD GEPPS CROSS SA 5094 | H36: DOWNER EDI SERVICES PTY LTD (ABN: 71 137 732 042) | I36: Utilities | J36: kWh | K36: 22458 | L36: AGL | M36: Origin | N36: 46204 | O36: 46934 | P36: 24 months | Q36: {=IFERROR(ROUNDUP(_xlfn.XLOOKUP(A36,'Budget FY26-28'!A:A,'Budget FY26-28'!M:O)*(1+Summary!$C$2), -2), "")} | R36: 9200 | S36: 9200 | T36: Ready | V36: 7099171253_2001130961 | W36: Electricity Small Market | X36: Electricity [kWh] | Y36: AGL | Z36: Gepps Cross | AB36: Active | AC36: Connection ID is the account number suffix | AD36: 8404807400_2001130961; 500012733985_2001130961; 500014182603_2001130961
A37: 2001160686 | B37: Electricity | C37: Australia | D37: SA | E37: AU Small Energy | F37: Roads Workshop Wingfield | G37: 553-557 GRAND JUNCTION ROAD WINGFIELD SA 5013 | H37: DOWNER EDI SERVICES PTY LTD (ABN: 71 137 732 042) | I37: ROAD SERVICES | J37: kWh | K37: 36782 | L37: AGL | M37: Origin | N37: 46204 | O37: 46934 | P37: 24 months | Q37: {=IFERROR(ROUNDUP(_xlfn.XLOOKUP(A37,'Budget FY26-28'!A:A,'Budget FY26-28'!M:O)*(1+Summary!$C$2), -2), "")} | R37: 14000 | S37: 14000 | T37: Ready | V37: 7099172129_2001160686 | W37: Electricity Small Market | X37: Electricity [kWh] | Y37: AGL | Z37: Asphalt Prod - Wingfield (523) | AA37: 523 | AB37: Active | AC37: Connection ID is the account number suffix | AD37: 500006951122_2001160686 | AE37: LGCS_2002254877 (at this location, different ID) - historical
A38: 2001223248 | B38: Electricity | C38: Australia | D38: SA | E38: AU Small Energy | F38: 326 Kidman Park, SA | G38: 326 GRANGE RD KIDMAN PARK SA | H38: DOWNER UTILITIES AUSTRALIA PTY LTD (ABN: 65 075 194 857) | I38: E&U | J38: kWh | K38: 5840 | L38: AGL | M38: Origin | N38: 46204 | O38: 46934 | P38: 24 months | Q38: {=IFERROR(ROUNDUP(_xlfn.XLOOKUP(A38,'Budget FY26-28'!A:A,'Budget FY26-28'!M:O)*(1+Summary!$C$2), -2), "")} | R38: 2900 | S38: 2900 | T38: Ready | V38: Not found | AC38: No Envizi account ends in this Connection ID
A39: 2001341166 | B39: Electricity | C39: Australia | D39: SA | E39: AU Small Energy | F39: DM Roads -Sturt Depot | G39: Lot 100 / 78 Sturt Rd Bedford Park SA 5042 | H39: DOWNER EDI WORKS PTY LTD (ABN: 66 008 709 608) | I39: ROAD SERVICES | J39: kWh | K39: 3902 | L39: AGL | M39: Origin | N39: 46204 | O39: 46934 | P39: 24 months | Q39: {=IFERROR(ROUNDUP(_xlfn.XLOOKUP(A39,'Budget FY26-28'!A:A,'Budget FY26-28'!M:O)*(1+Summary!$C$2), -2), "")} | R39: 2000 | S39: 2000 | T39: Ready | V39: 7099171261_2001341166 | W39: Electricity Small Market | X39: Electricity [kWh] | Y39: AGL | Z39: Sturt | AA39: 17021267 | AB39: Active | AC39: Connection ID is the account number suffix | AD39: 4304586748_2001341166; 500015155756_2001341166
A40: 2001341167 | B40: Electricity | C40: Australia | D40: SA | E40: AU Small Energy | F40: DM Roads- Sturt Depot | G40: 331 Sturt Rd Bedford Park SA 5042 | H40: DOWNER EDI WORKS PTY LTD (ABN: 66 008 709 608) | I40: ROAD SERVICES | J40: kWh | K40: 21166 | L40: AGL | M40: Origin | N40: 46204 | O40: 46934 | P40: 24 months | Q40: {=IFERROR(ROUNDUP(_xlfn.XLOOKUP(A40,'Budget FY26-28'!A:A,'Budget FY26-28'!M:O)*(1+Summary!$C$2), -2), "")} | R40: 8000 | S40: 8000 | T40: Ready | V40: 7099172137_2001341167 | W40: Electricity Small Market | X40: Electricity [kWh] | Y40: AGL | Z40: Sturt | AA40: 17021267 | AB40: Active | AC40: Connection ID is the account number suffix | AD40: 4938159759_2001341167; 5372802078_2001341167; 500016287640_2001341167
...

Sheet Budget FY26-28
A1: FY26–FY28 Budget
A2: Connection ID | B2: Country | C2: Commodity | D2: State / Region | E2: Portfolio Group | F2: Units | G2: Annual Consumption | H2: Contract Start | I2: Contract End | J2: Currency | K2: Annual Input (current term) | L2: Renewal / FY28 Input | M2: FY26 Budget | N2: FY27 Budget | O2: FY28 Budget | P2: Budget Status | Q2: Notes
A3: 5265773931 | B3: {=_xlfn.XLOOKUP(A3,'Site Register'!A:A,'Site Register'!B:E)} | C3: Australia | D3: ACT | E3: AU Large Natural Gas | F3: GJ | G3: 30729.026 | H3: 46388 | I3: 47483 | J3: AUD | K3: ='Rate Inputs'!E134 | L3: ='Rate Inputs'!F134 | M3: =IF(OR($P3="Ready",$P3="FY26 provisional",$P3="FY26 secured"),IF($H3<=DATE(2025,7,1),ROUNDUP($K3,-2),IF('Rate Inputs'!$J134="","",ROUNDUP(IF($H3>DATE(2026,6,30),'Rate Inputs'!$J134,'Rate Inputs'!$J134*($H3-DATE(2025,7,1))/365+$K3*(DATE(2026,6,30)-$H3+1)/365),-2))),"") | N3: =IF($P3="Ready",ROUNDUP(IFERROR($K3,0),-2),IF(OR($P3="FY26 provisional",$P3="FY26 secured"),"",0)) | O3: =IF($P3="Ready",IF('Rate Inputs'!$F134="","",ROUNDUP(IFERROR($L3,0),-2)),IF(OR($P3="FY26 provisional",$P3="FY26 secured"),"",0)) | P3: Ready
A4: 5242077399 | B4: {=_xlfn.XLOOKUP(A4,'Site Register'!A:A,'Site Register'!B:E)} | C4: Australia | D4: NSW | E4: AU Large Natural Gas | F4: GJ | G4: 19847.411 | H4: 46023 | I4: 46752 | J4: AUD | K4: ='Rate Inputs'!E136 | L4: ='Rate Inputs'!F136 | M4: =IF(OR($P4="Ready",$P4="FY26 provisional",$P4="FY26 secured"),IF($H4<=DATE(2025,7,1),ROUNDUP($K4,-2),IF('Rate Inputs'!$J136="","",ROUNDUP(IF($H4>DATE(2026,6,30),'Rate Inputs'!$J136,'Rate Inputs'!$J136*($H4-DATE(2025,7,1))/365+$K4*(DATE(2026,6,30)-$H4+1)/365),-2))),"") | N4: =IF($P4="Ready",ROUNDUP(IFERROR($K4,0),-2),IF(OR($P4="FY26 provisional",$P4="FY26 secured"),"",0)) | O4: =IF($P4="Ready",IF('Rate Inputs'!$F136="","",ROUNDUP(IFERROR($L4,0),-2)),IF(OR($P4="FY26 provisional",$P4="FY26 secured"),"",0)) | P4: Ready
A5: 5247064745 | B5: {=_xlfn.XLOOKUP(A5,'Site Register'!A:A,'Site Register'!B:E)} | C5: Australia | D5: NSW | E5: AU Large Natural Gas | F5: GJ | G5: 2500 | H5: 46388 | I5: 47483 | J5: AUD | K5: ='Rate Inputs'!E141 | L5: ='Rate Inputs'!F141 | M5: =IF(OR($P5="Ready",$P5="FY26 provisional",$P5="FY26 secured"),IF($H5<=DATE(2025,7,1),ROUNDUP($K5,-2),IF('Rate Inputs'!$J141="","",ROUNDUP(IF($H5>DATE(2026,6,30),'Rate Inputs'!$J141,'Rate Inputs'!$J141*($H5-DATE(2025,7,1))/365+$K5*(DATE(2026,6,30)-$H5+1)/365),-2))),"") | N5: =IF($P5="Ready",ROUNDUP(IFERROR($K5,0),-2),IF(OR($P5="FY26 provisional",$P5="FY26 secured"),"",0)) | O5: =IF($P5="Ready",IF('Rate Inputs'!$F141="","",ROUNDUP(IFERROR($L5,0),-2)),IF(OR($P5="FY26 provisional",$P5="FY26 secured"),"",0)) | P5: Ready
A6: 5248353654 | B6: {=_xlfn.XLOOKUP(A6,'Site Register'!A:A,'Site Register'!B:E)} | C6: Australia | D6: NSW | E6: AU Large Natural Gas | F6: GJ | G6: 108015.37 | H6: 46023 | I6: 46752 | J6: AUD | K6: ='Rate Inputs'!E147 | L6: ='Rate Inputs'!F147 | M6: =IF(OR($P6="Ready",$P6="FY26 provisional",$P6="FY26 secured"),IF($H6<=DATE(2025,7,1),ROUNDUP($K6,-2),IF('Rate Inputs'!$J147="","",ROUNDUP(IF($H6>DATE(2026,6,30),'Rate Inputs'!$J147,'Rate Inputs'!$J147*($H6-DATE(2025,7,1))/365+$K6*(DATE(2026,6,30)-$H6+1)/365),-2))),"") | N6: =IF($P6="Ready",ROUNDUP(IFERROR($K6,0),-2),IF(OR($P6="FY26 provisional",$P6="FY26 secured"),"",0)) | O6: =IF($P6="Ready",IF('Rate Inputs'!$F147="","",ROUNDUP(IFERROR($L6,0),-2)),IF(OR($P6="FY26 provisional",$P6="FY26 secured"),"",0)) | P6: Ready
A7: 5265761108 | B7: {=_xlfn.XLOOKUP(A7,'Site Register'!A:A,'Site Register'!B:E)} | C7: Australia | D7: NSW | E7: AU Large Natural Gas | F7: GJ | G7: 1300 | H7: 46388 | I7: 46752 | J7: AUD | K7: ='Rate Inputs'!E148 | L7: ='Rate Inputs'!F148 | M7: =IF(OR($P7="Ready",$P7="FY26 provisional",$P7="FY26 secured"),IF($H7<=DATE(2025,7,1),ROUNDUP($K7,-2),IF('Rate Inputs'!$J148="","",ROUNDUP(IF($H7>DATE(2026,6,30),'Rate Inputs'!$J148,'Rate Inputs'!$J148*($H7-DATE(2025,7,1))/365+$K7*(DATE(2026,6,30)-$H7+1)/365),-2))),"") | N7: =IF($P7="Ready",ROUNDUP(IFERROR($K7,0),-2),IF(OR($P7="FY26 provisional",$P7="FY26 secured"),"",0)) | O7: =IF($P7="Ready",IF('Rate Inputs'!$F148="","",ROUNDUP(IFERROR($L7,0),-2)),IF(OR($P7="FY26 provisional",$P7="FY26 secured"),"",0)) | P7: Ready
A8: 5510072233 | B8: {=_xlfn.XLOOKUP(A8,'Site Register'!A:A,'Site Register'!B:E)} | C8: Australia | D8: SA | E8: AU Large Natural Gas | F8: GJ | G8: 92565.36 | H8: 46023 | I8: 46752 | J8: AUD | K8: ='Rate Inputs'!E154 | L8: ='Rate Inputs'!F154 | M8: =IF(OR($P8="Ready",$P8="FY26 provisional",$P8="FY26 secured"),IF($H8<=DATE(2025,7,1),ROUNDUP($K8,-2),IF('Rate Inputs'!$J154="","",ROUNDUP(IF($H8>DATE(2026,6,30),'Rate Inputs'!$J154,'Rate Inputs'!$J154*($H8-DATE(2025,7,1))/365+$K8*(DATE(2026,6,30)-$H8+1)/365),-2))),"") | N8: =IF($P8="Ready",ROUNDUP(IFERROR($K8,0),-2),IF(OR($P8="FY26 provisional",$P8="FY26 secured"),"",0)) | O8: =IF($P8="Ready",IF('Rate Inputs'!$F154="","",ROUNDUP(IFERROR($L8,0),-2)),IF(OR($P8="FY26 provisional",$P8="FY26 secured"),"",0)) | P8: Ready
A9: 5510485000 | B9: {=_xlfn.XLOOKUP(A9,'Site Register'!A:A,'Site Register'!B:E)} | C9: Australia | D9: SA | E9: AU Large Natural Gas | F9: GJ | G9: 13214.104 | H9: 46023 | I9: 46752 | J9: AUD | K9: ='Rate Inputs'!E156 | L9: ='Rate Inputs'!F156 | M9: =IF(OR($P9="Ready",$P9="FY26 provisional",$P9="FY26 secured"),IF($H9<=DATE(2025,7,1),ROUNDUP($K9,-2),IF('Rate Inputs'!$J156="","",ROUNDUP(IF($H9>DATE(2026,6,30),'Rate Inputs'!$J156,'Rate Inputs'!$J156*($H9-DATE(2025,7,1))/365+$K9*(DATE(2026,6,30)-$H9+1)/365),-2))),"") | N9: =IF($P9="Ready",ROUNDUP(IFERROR($K9,0),-2),IF(OR($P9="FY26 provisional",$P9="FY26 secured"),"",0)) | O9: =IF($P9="Ready",IF('Rate Inputs'!$F156="","",ROUNDUP(IFERROR($L9,0),-2)),IF(OR($P9="FY26 provisional",$P9="FY26 secured"),"",0)) | P9: Ready
A10: 5762711908 | B10: {=_xlfn.XLOOKUP(A10,'Site Register'!A:A,'Site Register'!B:E)} | C10: Australia | D10: TAS | E10: AU Large Natural Gas | F10: GJ | G10: 15621.564 | H10: 45658 | I10: 46387 | J10: AUD | K10: ='Rate Inputs'!E157 | L10: =K10 | M10: =IF(OR($P10="Ready",$P10="FY26 provisional",$P10="FY26 secured"),IF($H10<=DATE(2025,7,1),ROUNDUP($K10,-2),IF('Rate Inputs'!$J157="","",ROUNDUP(IF($H10>DATE(2026,6,30),'Rate Inputs'!$J157,'Rate Inputs'!$J157*($H10-DATE(2025,7,1))/365+$K10*(DATE(2026,6,30)-$H10+1)/365),-2))),"") | N10: =IF($P10="Ready",ROUNDUP(IFERROR($K10,0),-2),IF(OR($P10="FY26 provisional",$P10="FY26 secured"),"",0)) | O10: =N10 | P10: Ready | Q10: Estimated FY27/FY28 based on FY26 contract
A11: 5310000243 | B11: {=_xlfn.XLOOKUP(A11,'Site Register'!A:A,'Site Register'!B:E)} | C11: Australia | D11: VIC | E11: AU Large Natural Gas | F11: GJ | G11: 57783.717 | H11: 46023 | I11: 46752 | J11: AUD | K11: ='Rate Inputs'!E158 | L11: ='Rate Inputs'!F158 | M11: =IF(OR($P11="Ready",$P11="FY26 provisional",$P11="FY26 secured"),IF($H11<=DATE(2025,7,1),ROUNDUP($K11,-2),IF('Rate Inputs'!$J158="","",ROUNDUP(IF($H11>DATE(2026,6,30),'Rate Inputs'!$J158,'Rate Inputs'!$J158*($H11-DATE(2025,7,1))/365+$K11*(DATE(2026,6,30)-$H11+1)/365),-2))),"") | N11: =IF($P11="Ready",ROUNDUP(IFERROR($K11,0),-2),IF(OR($P11="FY26 provisional",$P11="FY26 secured"),"",0)) | O11: =IF($P11="Ready",IF('Rate Inputs'!$F158="","",ROUNDUP(IFERROR($L11,0),-2)),IF(OR($P11="FY26 provisional",$P11="FY26 secured"),"",0)) | P11: Ready
A12: 5320000943 | B12: {=_xlfn.XLOOKUP(A12,'Site Register'!A:A,'Site Register'!B:E)} | C12: Australia | D12: VIC | E12: AU Large Natural Gas | F12: GJ | G12: 23114.486 | H12: 46023 | I12: 46752 | J12: AUD | K12: ='Rate Inputs'!E159 | L12: ='Rate Inputs'!F159 | M12: =IF(OR($P12="Ready",$P12="FY26 provisional",$P12="FY26 secured"),IF($H12<=DATE(2025,7,1),ROUNDUP($K12,-2),IF('Rate Inputs'!$J159="","",ROUNDUP(IF($H12>DATE(2026,6,30),'Rate Inputs'!$J159,'Rate Inputs'!$J159*($H12-DATE(2025,7,1))/365+$K12*(DATE(2026,6,30)-$H12+1)/365),-2))),"") | N12: =IF($P12="Ready",ROUNDUP(IFERROR($K12,0),-2),IF(OR($P12="FY26 provisional",$P12="FY26 secured"),"",0)) | O12: =IF($P12="Ready",IF('Rate Inputs'!$F159="","",ROUNDUP(IFERROR($L12,0),-2)),IF(OR($P12="FY26 provisional",$P12="FY26 secured"),"",0)) | P12: Ready
A13: 5330662312 | B13: {=_xlfn.XLOOKUP(A13,'Site Register'!A:A,'Site Register'!B:E)} | C13: Australia | D13: VIC | E13: AU Large Natural Gas | F13: GJ | G13: 103871.24 | H13: 46023 | I13: 46752 | J13: AUD | K13: ='Rate Inputs'!E161 | L13: ='Rate Inputs'!F161 | M13: =IF(OR($P13="Ready",$P13="FY26 provisional",$P13="FY26 secured"),IF($H13<=DATE(2025,7,1),ROUNDUP($K13,-2),IF('Rate Inputs'!$J161="","",ROUNDUP(IF($H13>DATE(2026,6,30),'Rate Inputs'!$J161,'Rate Inputs'!$J161*($H13-DATE(2025,7,1))/365+$K13*(DATE(2026,6,30)-$H13+1)/365),-2))),"") | N13: =IF($P13="Ready",ROUNDUP(IFERROR($K13,0),-2),IF(OR($P13="FY26 provisional",$P13="FY26 secured"),"",0)) | O13: =IF($P13="Ready",IF('Rate Inputs'!$F161="","",ROUNDUP(IFERROR($L13,0),-2)),IF(OR($P13="FY26 provisional",$P13="FY26 secured"),"",0)) | P13: Ready
A14: 5600405263 | B14: {=_xlfn.XLOOKUP(A14,'Site Register'!A:A,'Site Register'!B:E)} | C14: Australia | D14: WA | E14: AU Large Natural Gas | F14: GJ | G14: 590 | H14: 46023 | I14: 46752 | J14: AUD | K14: ='Rate Inputs'!E162 | L14: ='Rate Inputs'!F162 | M14: =IF(OR($P14="Ready",$P14="FY26 provisional",$P14="FY26 secured"),IF($H14<=DATE(2025,7,1),ROUNDUP($K14,-2),IF('Rate Inputs'!$J162="","",ROUNDUP(IF($H14>DATE(2026,6,30),'Rate Inputs'!$J162,'Rate Inputs'!$J162*($H14-DATE(2025,7,1))/365+$K14*(DATE(2026,6,30)-$H14+1)/365),-2))),"") | N14: =IF($P14="Ready",ROUNDUP(IFERROR($K14,0),-2),IF(OR($P14="FY26 provisional",$P14="FY26 secured"),"",0)) | O14: =N14 | P14: Ready | Q14: Estimated FY28 based on FY27 contract
A15: 5600436929 | B15: {=_xlfn.XLOOKUP(A15,'Site Register'!A:A,'Site Register'!B:E)} | C15: Australia | D15: WA | E15: AU Large Natural Gas | F15: GJ | G15: 23242.137 | H15: 46023 | I15: 46752 | J15: AUD | K15: ='Rate Inputs'!E163 | L15: ='Rate Inputs'!F163 | M15: =IF(OR($P15="Ready",$P15="FY26 provisional",$P15="FY26 secured"),IF($H15<=DATE(2025,7,1),ROUNDUP($K15,-2),IF('Rate Inputs'!$J163="","",ROUNDUP(IF($H15>DATE(2026,6,30),'Rate Inputs'!$J163,'Rate Inputs'!$J163*($H15-DATE(2025,7,1))/365+$K15*(DATE(2026,6,30)-$H15+1)/365),-2))),"") | N15: =IF($P15="Ready",ROUNDUP(IFERROR($K15,0),-2),IF(OR($P15="FY26 provisional",$P15="FY26 secured"),"",0)) | O15: =N15 | P15: Ready | Q15: Estimated FY28 based on FY27 contract
A16: 5600604830 | B16: {=_xlfn.XLOOKUP(A16,'Site Register'!A:A,'Site Register'!B:E)} | C16: Australia | D16: WA | E16: AU Large Natural Gas | F16: GJ | G16: 9471.6073 | H16: 46023 | I16: 46752 | J16: AUD | K16: ='Rate Inputs'!E164 | L16: ='Rate Inputs'!F164 | M16: =IF(OR($P16="Ready",$P16="FY26 provisional",$P16="FY26 secured"),IF($H16<=DATE(2025,7,1),ROUNDUP($K16,-2),IF('Rate Inputs'!$J164="","",ROUNDUP(IF($H16>DATE(2026,6,30),'Rate Inputs'!$J164,'Rate Inputs'!$J164*($H16-DATE(2025,7,1))/365+$K16*(DATE(2026,6,30)-$H16+1)/365),-2))),"") | N16: =IF($P16="Ready",ROUNDUP(IFERROR($K16,0),-2),IF(OR($P16="FY26 provisional",$P16="FY26 secured"),"",0)) | O16: =N16 | P16: Ready | Q16: Estimated FY28 based on FY27 contract
A17: 5600945901 | B17: {=_xlfn.XLOOKUP(A17,'Site Register'!A:A,'Site Register'!B:E)} | C17: Australia | D17: WA | E17: AU Large Natural Gas | F17: GJ | G17: 34066.928 | H17: 46023 | I17: 46752 | J17: AUD | K17: ='Rate Inputs'!E165 | L17: ='Rate Inputs'!F165 | M17: =IF(OR($P17="Ready",$P17="FY26 provisional",$P17="FY26 secured"),IF($H17<=DATE(2025,7,1),ROUNDUP($K17,-2),IF('Rate Inputs'!$J165="","",ROUNDUP(IF($H17>DATE(2026,6,30),'Rate Inputs'!$J165,'Rate Inputs'!$J165*($H17-DATE(2025,7,1))/365+$K17*(DATE(2026,6,30)-$H17+1)/365),-2))),"") | N17: =IF($P17="Ready",ROUNDUP(IFERROR($K17,0),-2),IF(OR($P17="FY26 provisional",$P17="FY26 secured"),"",0)) | O17: =N17 | P17: Ready | Q17: Estimated FY28 based on FY27 contract
A18: 3053253239 | B18: {=_xlfn.XLOOKUP(A18,'Site Register'!A:A,'Site Register'!B:E)} | C18: Australia | D18: QLD | E18: AU Large Electricity | F18: kWh | G18: 6208798 | H18: 46204 | I18: 46934 | J18: AUD | K18: ='Rate Inputs'!E59 | L18: ='Rate Inputs'!F59 | M18: =IF(OR($P18="Ready",$P18="FY26 provisional",$P18="FY26 secured"),IF($H18<=DATE(2025,7,1),ROUNDUP($K18,-2),IF('Rate Inputs'!$J59="","",ROUNDUP(IF($H18>DATE(2026,6,30),'Rate Inputs'!$J59,'Rate Inputs'!$J59*($H18-DATE(2025,7,1))/365+$K18*(DATE(2026,6,30)-$H18+1)/365),-2))),"") | N18: =IF($P18="Ready",ROUNDUP(IFERROR($K18,0),-2),IF(OR($P18="FY26 provisional",$P18="FY26 secured"),"",0)) | O18: =IF($P18="Ready",IF('Rate Inputs'!$F59="","",ROUNDUP(IFERROR($L18,0),-2)),IF(OR($P18="FY26 provisional",$P18="FY26 secured"),"",0)) | P18: Ready
A19: 6305885252 | B19: {=_xlfn.XLOOKUP(A19,'Site Register'!A:A,'Site Register'!B:E)} | C19: Australia | D19: VIC | E19: AU Large Electricity | F19: kWh | G19: 201844 | H19: 46204 | I19: 46934 | J19: AUD | K19: ='Rate Inputs'!E116 | L19: ='Rate Inputs'!F116 | M19: =IF(OR($P19="Ready",$P19="FY26 provisional",$P19="FY26 secured"),IF($H19<=DATE(2025,7,1),ROUNDUP($K19,-2),IF('Rate Inputs'!$J116="","",ROUNDUP(IF($H19>DATE(2026,6,30),'Rate Inputs'!$J116,'Rate Inputs'!$J116*($H19-DATE(2025,7,1))/365+$K19*(DATE(2026,6,30)-$H19+1)/365),-2))),"") | N19: =IF($P19="Ready",ROUNDUP(IFERROR($K19,0),-2),IF(OR($P19="FY26 provisional",$P19="FY26 secured"),"",0)) | O19: =IF($P19="Ready",IF('Rate Inputs'!$F116="","",ROUNDUP(IFERROR($L19,0),-2)),IF(OR($P19="FY26 provisional",$P19="FY26 secured"),"",0)) | P19: Ready
A20: 4001050448 | B20: {=_xlfn.XLOOKUP(A20,'Site Register'!A:A,'Site Register'!B:E)} | C20: Australia | D20: NSW | E20: AU Small Energy | F20: kWh | G20: 28354 | H20: 46204 | I20: 46934 | J20: AUD | K20: ='Rate Inputs'!E4 | L20: ='Rate Inputs'!F4 | M20: =IF(OR($P20="Ready",$P20="FY26 provisional",$P20="FY26 secured"),IF($H20<=DATE(2025,7,1),ROUNDUP($K20,-2),IF('Rate Inputs'!$J4="","",ROUNDUP(IF($H20>DATE(2026,6,30),'Rate Inputs'!$J4,'Rate Inputs'!$J4*($H20-DATE(2025,7,1))/365+$K20*(DATE(2026,6,30)-$H20+1)/365),-2))),"") | N20: =IF($P20="Ready",ROUNDUP(IFERROR($K20,0),-2),IF(OR($P20="FY26 provisional",$P20="FY26 secured"),"",0)) | O20: =IF($P20="Ready",IF('Rate Inputs'!$F4="","",ROUNDUP(IFERROR($L20,0),-2)),IF(OR($P20="FY26 provisional",$P20="FY26 secured"),"",0)) | P20: Ready
A21: 4001128707 | B21: {=_xlfn.XLOOKUP(A21,'Site Register'!A:A,'Site Register'!B:E)} | C21: Australia | D21: NSW | E21: AU Small Energy | F21: kWh | G21: 0 | H21: 46204 | I21: 46934 | J21: AUD | K21: ='Rate Inputs'!E6 | L21: ='Rate Inputs'!F6 | M21: =IF(OR($P21="Ready",$P21="FY26 provisional",$P21="FY26 secured"),IF($H21<=DATE(2025,7,1),ROUNDUP($K21,-2),IF('Rate Inputs'!$J6="","",ROUNDUP(IF($H21>DATE(2026,6,30),'Rate Inputs'!$J6,'Rate Inputs'!$J6*($H21-DATE(2025,7,1))/365+$K21*(DATE(2026,6,30)-$H21+1)/365),-2))),"") | N21: =IF($P21="Ready",ROUNDUP(IFERROR($K21,0),-2),IF(OR($P21="FY26 provisional",$P21="FY26 secured"),"",0)) | O21: =IF($P21="Ready",IF('Rate Inputs'!$F6="","",ROUNDUP(IFERROR($L21,0),-2)),IF(OR($P21="FY26 provisional",$P21="FY26 secured"),"",0)) | P21: Review required
A22: 4001174306 | B22: {=_xlfn.XLOOKUP(A22,'Site Register'!A:A,'Site Register'!B:E)} | C22: Australia | D22: NSW | E22: AU Small Energy | F22: kWh | G22: 254401 | H22: 46204 | I22: 46934 | J22: AUD | K22: ='Rate Inputs'!E8 | L22: ='Rate Inputs'!F8 | M22: =IF(OR($P22="Ready",$P22="FY26 provisional",$P22="FY26 secured"),IF($H22<=DATE(2025,7,1),ROUNDUP($K22,-2),IF('Rate Inputs'!$J8="","",ROUNDUP(IF($H22>DATE(2026,6,30),'Rate Inputs'!$J8,'Rate Inputs'!$J8*($H22-DATE(2025,7,1))/365+$K22*(DATE(2026,6,30)-$H22+1)/365),-2))),"") | N22: =IF($P22="Ready",ROUNDUP(IFERROR($K22,0),-2),IF(OR($P22="FY26 provisional",$P22="FY26 secured"),"",0)) | O22: =IF($P22="Ready",IF('Rate Inputs'!$F8="","",ROUNDUP(IFERROR($L22,0),-2)),IF(OR($P22="FY26 provisional",$P22="FY26 secured"),"",0)) | P22: Ready
A23: 4001231357 | B23: {=_xlfn.XLOOKUP(A23,'Site Register'!A:A,'Site Register'!B:E)} | C23: Australia | D23: NSW | E23: AU Small Energy | F23: kWh | G23: 30776 | H23: 46204 | I23: 46934 | J23: AUD | K23: ='Rate Inputs'!E11 | L23: ='Rate Inputs'!F11 | M23: =IF(OR($P23="Ready",$P23="FY26 provisional",$P23="FY26 secured"),IF($H23<=DATE(2025,7,1),ROUNDUP($K23,-2),IF('Rate Inputs'!$J11="","",ROUNDUP(IF($H23>DATE(2026,6,30),'Rate Inputs'!$J11,'Rate Inputs'!$J11*($H23-DATE(2025,7,1))/365+$K23*(DATE(2026,6,30)-$H23+1)/365),-2))),"") | N23: =IF($P23="Ready",ROUNDUP(IFERROR($K23,0),-2),IF(OR($P23="FY26 provisional",$P23="FY26 secured"),"",0)) | O23: =IF($P23="Ready",IF('Rate Inputs'!$F11="","",ROUNDUP(IFERROR($L23,0),-2)),IF(OR($P23="FY26 provisional",$P23="FY26 secured"),"",0)) | P23: Ready
A24: 4001277522 | B24: {=_xlfn.XLOOKUP(A24,'Site Register'!A:A,'Site Register'!B:E)} | C24: Australia | D24: NSW | E24: AU Small Energy | F24: kWh | G24: 9299 | H24: 46204 | I24: 46934 | J24: AUD | K24: ='Rate Inputs'!E12 | L24: ='Rate Inputs'!F12 | M24: =IF(OR($P24="Ready",$P24="FY26 provisional",$P24="FY26 secured"),IF($H24<=DATE(2025,7,1),ROUNDUP($K24,-2),IF('Rate Inputs'!$J12="","",ROUNDUP(IF($H24>DATE(2026,6,30),'Rate Inputs'!$J12,'Rate Inputs'!$J12*($H24-DATE(2025,7,1))/365+$K24*(DATE(2026,6,30)-$H24+1)/365),-2))),"") | N24: =IF($P24="Ready",ROUNDUP(IFERROR($K24,0),-2),IF(OR($P24="FY26 provisional",$P24="FY26 secured"),"",0)) | O24: =IF($P24="Ready",IF('Rate Inputs'!$F12="","",ROUNDUP(IFERROR($L24,0),-2)),IF(OR($P24="FY26 provisional",$P24="FY26 secured"),"",0)) | P24: Ready
A25: 4103512903 | B25: {=_xlfn.XLOOKUP(A25,'Site Register'!A:A,'Site Register'!B:E)} | C25: Australia | D25: NSW | E25: AU Small Energy | F25: kWh | G25: 15039 | H25: 46204 | I25: 46934 | J25: AUD | K25: ='Rate Inputs'!E14 | L25: ='Rate Inputs'!F14 | M25: =IF(OR($P25="Ready",$P25="FY26 provisional",$P25="FY26 secured"),IF($H25<=DATE(2025,7,1),ROUNDUP($K25,-2),IF('Rate Inputs'!$J14="","",ROUNDUP(IF($H25>DATE(2026,6,30),'Rate Inputs'!$J14,'Rate Inputs'!$J14*($H25-DATE(2025,7,1))/365+$K25*(DATE(2026,6,30)-$H25+1)/365),-2))),"") | N25: =IF($P25="Ready",ROUNDUP(IFERROR($K25,0),-2),IF(OR($P25="FY26 provisional",$P25="FY26 secured"),"",0)) | O25: =IF($P25="Ready",IF('Rate Inputs'!$F14="","",ROUNDUP(IFERROR($L25,0),-2)),IF(OR($P25="FY26 provisional",$P25="FY26 secured"),"",0)) | P25: Ready
A26: 4104037195 | B26: {=_xlfn.XLOOKUP(A26,'Site Register'!A:A,'Site Register'!B:E)} | C26: Australia | D26: NSW | E26: AU Small Energy | F26: kWh | G26: 2938 | H26: 46204 | I26: 46934 | J26: AUD | K26: ='Rate Inputs'!E33 | L26: ='Rate Inputs'!F33 | M26: =IF(OR($P26="Ready",$P26="FY26 provisional",$P26="FY26 secured"),IF($H26<=DATE(2025,7,1),ROUNDUP($K26,-2),IF('Rate Inputs'!$J33="","",ROUNDUP(IF($H26>DATE(2026,6,30),'Rate Inputs'!$J33,'Rate Inputs'!$J33*($H26-DATE(2025,7,1))/365+$K26*(DATE(2026,6,30)-$H26+1)/365),-2))),"") | N26: =IF($P26="Ready",ROUNDUP(IFERROR($K26,0),-2),IF(OR($P26="FY26 provisional",$P26="FY26 secured"),"",0)) | O26: =IF($P26="Ready",IF('Rate Inputs'!$F33="","",ROUNDUP(IFERROR($L26,0),-2)),IF(OR($P26="FY26 provisional",$P26="FY26 secured"),"",0)) | P26: Ready
A27: 4204234430 | B27: {=_xlfn.XLOOKUP(A27,'Site Register'!A:A,'Site Register'!B:E)} | C27: Australia | D27: NSW | E27: AU Small Energy | F27: kWh | G27: 16709 | H27: 46204 | I27: 46934 | J27: AUD | K27: ='Rate Inputs'!E35 | L27: ='Rate Inputs'!F35 | M27: =IF(OR($P27="Ready",$P27="FY26 provisional",$P27="FY26 secured"),IF($H27<=DATE(2025,7,1),ROUNDUP($K27,-2),IF('Rate Inputs'!$J35="","",ROUNDUP(IF($H27>DATE(2026,6,30),'Rate Inputs'!$J35,'Rate Inputs'!$J35*($H27-DATE(2025,7,1))/365+$K27*(DATE(2026,6,30)-$H27+1)/365),-2))),"") | N27: =IF($P27="Ready",ROUNDUP(IFERROR($K27,0),-2),IF(OR($P27="FY26 provisional",$P27="FY26 secured"),"",0)) | O27: =IF($P27="Ready",IF('Rate Inputs'!$F35="","",ROUNDUP(IFERROR($L27,0),-2)),IF(OR($P27="FY26 provisional",$P27="FY26 secured"),"",0)) | P27: Ready
A28: 4310027807 | B28: {=_xlfn.XLOOKUP(A28,'Site Register'!A:A,'Site Register'!B:E)} | C28: Australia | D28: NSW | E28: AU Small Energy | F28: kWh | G28: 65379 | H28: 46204 | I28: 46934 | J28: AUD | K28: ='Rate Inputs'!E36 | L28: ='Rate Inputs'!F36 | M28: =IF(OR($P28="Ready",$P28="FY26 provisional",$P28="FY26 secured"),IF($H28<=DATE(2025,7,1),ROUNDUP($K28,-2),IF('Rate Inputs'!$J36="","",ROUNDUP(IF($H28>DATE(2026,6,30),'Rate Inputs'!$J36,'Rate Inputs'!$J36*($H28-DATE(2025,7,1))/365+$K28*(DATE(2026,6,30)-$H28+1)/365),-2))),"") | N28: =IF($P28="Ready",ROUNDUP(IFERROR($K28,0),-2),IF(OR($P28="FY26 provisional",$P28="FY26 secured"),"",0)) | O28: =IF($P28="Ready",IF('Rate Inputs'!$F36="","",ROUNDUP(IFERROR($L28,0),-2)),IF(OR($P28="FY26 provisional",$P28="FY26 secured"),"",0)) | P28: Ready
A29: 4311422527 | B29: {=_xlfn.XLOOKUP(A29,'Site Register'!A:A,'Site Register'!B:E)} | C29: Australia | D29: NSW | E29: AU Small Energy | F29: kWh | G29: 33060 | H29: 46204 | I29: 46934 | J29: AUD | K29: ='Rate Inputs'!E47 | L29: ='Rate Inputs'!F47 | M29: =IF(OR($P29="Ready",$P29="FY26 provisional",$P29="FY26 secured"),IF($H29<=DATE(2025,7,1),ROUNDUP($K29,-2),IF('Rate Inputs'!$J47="","",ROUNDUP(IF($H29>DATE(2026,6,30),'Rate Inputs'!$J47,'Rate Inputs'!$J47*($H29-DATE(2025,7,1))/365+$K29*(DATE(2026,6,30)-$H29+1)/365),-2))),"") | N29: =IF($P29="Ready",ROUNDUP(IFERROR($K29,0),-2),IF(OR($P29="FY26 provisional",$P29="FY26 secured"),"",0)) | O29: =IF($P29="Ready",IF('Rate Inputs'!$F47="","",ROUNDUP(IFERROR($L29,0),-2)),IF(OR($P29="FY26 provisional",$P29="FY26 secured"),"",0)) | P29: Ready
A30: 4407159044 | B30: {=_xlfn.XLOOKUP(A30,'Site Register'!A:A,'Site Register'!B:E)} | C30: Australia | D30: NSW | E30: AU Small Energy | F30: kWh | G30: 33872 | H30: 46204 | I30: 46934 | J30: AUD | K30: ='Rate Inputs'!E48 | L30: ='Rate Inputs'!F48 | M30: =IF(OR($P30="Ready",$P30="FY26 provisional",$P30="FY26 secured"),IF($H30<=DATE(2025,7,1),ROUNDUP($K30,-2),IF('Rate Inputs'!$J48="","",ROUNDUP(IF($H30>DATE(2026,6,30),'Rate Inputs'!$J48,'Rate Inputs'!$J48*($H30-DATE(2025,7,1))/365+$K30*(DATE(2026,6,30)-$H30+1)/365),-2))),"") | N30: =IF($P30="Ready",ROUNDUP(IFERROR($K30,0),-2),IF(OR($P30="FY26 provisional",$P30="FY26 secured"),"",0)) | O30: =IF($P30="Ready",IF('Rate Inputs'!$F48="","",ROUNDUP(IFERROR($L30,0),-2)),IF(OR($P30="FY26 provisional",$P30="FY26 secured"),"",0)) | P30: Ready
A31: 3038502933 | B31: {=_xlfn.XLOOKUP(A31,'Site Register'!A:A,'Site Register'!B:E)} | C31: Australia | D31: QLD | E31: AU Small Energy | F31: kWh | G31: 38380 | H31: 46204 | I31: 46934 | J31: AUD | K31: ='Rate Inputs'!E55 | L31: ='Rate Inputs'!F55 | M31: =IF(OR($P31="Ready",$P31="FY26 provisional",$P31="FY26 secured"),IF($H31<=DATE(2025,7,1),ROUNDUP($K31,-2),IF('Rate Inputs'!$J55="","",ROUNDUP(IF($H31>DATE(2026,6,30),'Rate Inputs'!$J55,'Rate Inputs'!$J55*($H31-DATE(2025,7,1))/365+$K31*(DATE(2026,6,30)-$H31+1)/365),-2))),"") | N31: =IF($P31="Ready",ROUNDUP(IFERROR($K31,0),-2),IF(OR($P31="FY26 provisional",$P31="FY26 secured"),"",0)) | O31: =IF($P31="Ready",IF('Rate Inputs'!$F55="","",ROUNDUP(IFERROR($L31,0),-2)),IF(OR($P31="FY26 provisional",$P31="FY26 secured"),"",0)) | P31: Ready
A32: 3039040879 | B32: {=_xlfn.XLOOKUP(A32,'Site Register'!A:A,'Site Register'!B:E)} | C32: Australia | D32: QLD | E32: AU Small Energy | F32: kWh | G32: 70195 | H32: 46204 | I32: 46934 | J32: AUD | K32: ='Rate Inputs'!E56 | L32: ='Rate Inputs'!F56 | M32: =IF(OR($P32="Ready",$P32="FY26 provisional",$P32="FY26 secured"),IF($H32<=DATE(2025,7,1),ROUNDUP($K32,-2),IF('Rate Inputs'!$J56="","",ROUNDUP(IF($H32>DATE(2026,6,30),'Rate Inputs'!$J56,'Rate Inputs'!$J56*($H32-DATE(2025,7,1))/365+$K32*(DATE(2026,6,30)-$H32+1)/365),-2))),"") | N32: =IF($P32="Ready",ROUNDUP(IFERROR($K32,0),-2),IF(OR($P32="FY26 provisional",$P32="FY26 secured"),"",0)) | O32: =IF($P32="Ready",IF('Rate Inputs'!$F56="","",ROUNDUP(IFERROR($L32,0),-2)),IF(OR($P32="FY26 provisional",$P32="FY26 secured"),"",0)) | P32: Ready
A33: 3041781236 | B33: {=_xlfn.XLOOKUP(A33,'Site Register'!A:A,'Site Register'!B:E)} | C33: Australia | D33: QLD | E33: AU Small Energy | F33: kWh | G33: 53331 | H33: 46204 | I33: 46934 | J33: AUD | K33: ='Rate Inputs'!E57 | L33: ='Rate Inputs'!F57 | M33: =IF(OR($P33="Ready",$P33="FY26 provisional",$P33="FY26 secured"),IF($H33<=DATE(2025,7,1),ROUNDUP($K33,-2),IF('Rate Inputs'!$J57="","",ROUNDUP(IF($H33>DATE(2026,6,30),'Rate Inputs'!$J57,'Rate Inputs'!$J57*($H33-DATE(2025,7,1))/365+$K33*(DATE(2026,6,30)-$H33+1)/365),-2))),"") | N33: =IF($P33="Ready",ROUNDUP(IFERROR($K33,0),-2),IF(OR($P33="FY26 provisional",$P33="FY26 secured"),"",0)) | O33: =IF($P33="Ready",IF('Rate Inputs'!$F57="","",ROUNDUP(IFERROR($L33,0),-2)),IF(OR($P33="FY26 provisional",$P33="FY26 secured"),"",0)) | P33: Ready
A34: QB07736452 | B34: {=_xlfn.XLOOKUP(A34,'Site Register'!A:A,'Site Register'!B:E)} | C34: Australia | D34: QLD | E34: AU Small Energy | F34: kWh | G34: 24596 | H34: 46204 | I34: 46934 | J34: AUD | K34: ='Rate Inputs'!E72 | L34: ='Rate Inputs'!F72 | M34: =IF(OR($P34="Ready",$P34="FY26 provisional",$P34="FY26 secured"),IF($H34<=DATE(2025,7,1),ROUNDUP($K34,-2),IF('Rate Inputs'!$J72="","",ROUNDUP(IF($H34>DATE(2026,6,30),'Rate Inputs'!$J72,'Rate Inputs'!$J72*($H34-DATE(2025,7,1))/365+$K34*(DATE(2026,6,30)-$H34+1)/365),-2))),"") | N34: =IF($P34="Ready",ROUNDUP(IFERROR($K34,0),-2),IF(OR($P34="FY26 provisional",$P34="FY26 secured"),"",0)) | O34: =IF($P34="Ready",IF('Rate Inputs'!$F72="","",ROUNDUP(IFERROR($L34,0),-2)),IF(OR($P34="FY26 provisional",$P34="FY26 secured"),"",0)) | P34: Ready
A35: QB13869604 | B35: {=_xlfn.XLOOKUP(A35,'Site Register'!A:A,'Site Register'!B:E)} | C35: Australia | D35: QLD | E35: AU Small Energy | F35: kWh | G35: 16289 | H35: 46204 | I35: 46934 | J35: AUD | K35: ='Rate Inputs'!E73 | L35: ='Rate Inputs'!F73 | M35: =IF(OR($P35="Ready",$P35="FY26 provisional",$P35="FY26 secured"),IF($H35<=DATE(2025,7,1),ROUNDUP($K35,-2),IF('Rate Inputs'!$J73="","",ROUNDUP(IF($H35>DATE(2026,6,30),'Rate Inputs'!$J73,'Rate Inputs'!$J73*($H35-DATE(2025,7,1))/365+$K35*(DATE(2026,6,30)-$H35+1)/365),-2))),"") | N35: =IF($P35="Ready",ROUNDUP(IFERROR($K35,0),-2),IF(OR($P35="FY26 provisional",$P35="FY26 secured"),"",0)) | O35: =IF($P35="Ready",IF('Rate Inputs'!$F73="","",ROUNDUP(IFERROR($L35,0),-2)),IF(OR($P35="FY26 provisional",$P35="FY26 secured"),"",0)) | P35: Ready
A36: 2001130961 | B36: {=_xlfn.XLOOKUP(A36,'Site Register'!A:A,'Site Register'!B:E)} | C36: Australia | D36: SA | E36: AU Small Energy | F36: kWh | G36: 22458 | H36: 46204 | I36: 46934 | J36: AUD | K36: ='Rate Inputs'!E76 | L36: ='Rate Inputs'!F76 | M36: =IF(OR($P36="Ready",$P36="FY26 provisional",$P36="FY26 secured"),IF($H36<=DATE(2025,7,1),ROUNDUP($K36,-2),IF('Rate Inputs'!$J76="","",ROUNDUP(IF($H36>DATE(2026,6,30),'Rate Inputs'!$J76,'Rate Inputs'!$J76*($H36-DATE(2025,7,1))/365+$K36*(DATE(2026,6,30)-$H36+1)/365),-2))),"") | N36: =IF($P36="Ready",ROUNDUP(IFERROR($K36,0),-2),IF(OR($P36="FY26 provisional",$P36="FY26 secured"),"",0)) | O36: =IF($P36="Ready",IF('Rate Inputs'!$F76="","",ROUNDUP(IFERROR($L36,0),-2)),IF(OR($P36="FY26 provisional",$P36="FY26 secured"),"",0)) | P36: Ready
