Workbook

Sheet Summary
A1: RTS - market-based electricity check, Mar-Aug 26
A2: Source: Envizi electricity export taken 6 Sep 26 (Electricity Data as of 060926.xlsx), accounts only, Level 3 Group = Rail & Transit Systems (RTS). Chart figures are the Scope 1 & 2 monthly values read off the GHG Emissions YTD dashboard.
A4: Reconciliation to the dashboard (tCO2e)
A5: Line | B5: Mar 26 | C5: Apr 26 | D5: May 26 | E5: Jun 26 | F5: Jul 26 | G5: Aug 26 | H5: Basis
A6: Electricity - location-based Scope 2 | B6: =SUMIFS(Accounts!$N:$N,Accounts!$H:$H,"Mar 26") -> 666.9819 | C6: =SUMIFS(Accounts!$N:$N,Accounts!$H:$H,"Apr 26") -> 588.6631 | D6: =SUMIFS(Accounts!$N:$N,Accounts!$H:$H,"May 26") -> 672.4683 | E6: =SUMIFS(Accounts!$N:$N,Accounts!$H:$H,"Jun 26") -> 634.6193 | F6: =SUMIFS(Accounts!$N:$N,Accounts!$H:$H,"Jul 26") -> 739.0282 | G6: =SUMIFS(Accounts!$N:$N,Accounts!$H:$H,"Aug 26") -> 664.4571 | H6: Scope 2 reported, all RTS electricity accounts
A7: Certificates and renewable deductions (Other) | B7: =SUMIFS(Accounts!$O:$O,Accounts!$H:$H,"Mar 26") -> -140.7324 | C7: =SUMIFS(Accounts!$O:$O,Accounts!$H:$H,"Apr 26") -> -143.8634 | D7: =SUMIFS(Accounts!$O:$O,Accounts!$H:$H,"May 26") -> -159.2594 | E7: =SUMIFS(Accounts!$O:$O,Accounts!$H:$H,"Jun 26") -> -162.7664 | F7: =SUMIFS(Accounts!$O:$O,Accounts!$H:$H,"Jul 26") -> -572.7214 | G7: =SUMIFS(Accounts!$O:$O,Accounts!$H:$H,"Aug 26") -> -554.682 | H7: Other reported - the _CERTS virtual accounts and the Victorian 100% renewable deductions
A8: Electricity - market-based (Scope 2 + Other) | B8: =B6+B7 -> 526.2495 | C8: =C6+C7 -> 444.7997 | D8: =D6+D7 -> 513.2089 | E8: =E6+E7 -> 471.8529 | F8: =F6+F7 -> 166.3068 | G8: =G6+G7 -> 109.7751 | H8: What the certificates leave to report
A9: Dashboard Scope 1 & 2 (market-based) | B9: 625.05 | C9: 543.82 | D9: 612.33 | E9: 542.12 | F9: 928.48 | H9: Read off the chart; blank where the chart has no bar yet
A10: Dashboard less market-based electricity | B10: =IF(B9="","",B9-B8) -> 98.8005 | C10: =IF(C9="","",C9-C8) -> 99.0203 | D10: =IF(D9="","",D9-D8) -> 99.1211 | E10: =IF(E9="","",E9-E8) -> 70.2671 | F10: =IF(F9="","",F9-F8) -> 762.1732 | G10: =IF(G9="","",G9-G8) | H10: The non-electricity balance the dashboard implies (Scope 1 and anything else). Steady at ~99 t Mar-May and 70 t in Jun; 762 t in Jul
A11: Dashboard less location-based electricity | B11: =IF(B9="","",B9-B6) -> -41.9319 | C11: =IF(C9="","",C9-C6) -> -44.8431 | D11: =IF(D9="","",D9-D6) -> -60.1383 | E11: =IF(E9="","",E9-E6) -> -92.4993 | F11: =IF(F9="","",F9-F6) -> 189.4518 | G11: =IF(G9="","",G9-G6) | H11: Same test with no certificate credit at all
A12: Blue on yellow = typed in from the chart. Everything else is a formula over the Accounts tab.
A14: Market-based electricity by RTS location (Scope 2 + Other, tCO2e)
A15: Location | B15: Mar 26 | C15: Apr 26 | D15: May 26 | E15: Jun 26 | F15: Jul 26 | G15: Aug 26 | H15: Jul less Jun
A16: Auburn | B16: =SUMIFS(Accounts!$P:$P,Accounts!$A:$A,$A16,Accounts!$H:$H,"Mar 26") -> 246.5736 | C16: =SUMIFS(Accounts!$P:$P,Accounts!$A:$A,$A16,Accounts!$H:$H,"Apr 26") -> 187.5642 | D16: =SUMIFS(Accounts!$P:$P,Accounts!$A:$A,$A16,Accounts!$H:$H,"May 26") -> 224.4885 | E16: =SUMIFS(Accounts!$P:$P,Accounts!$A:$A,$A16,Accounts!$H:$H,"Jun 26") -> 179.1822 | F16: =SUMIFS(Accounts!$P:$P,Accounts!$A:$A,$A16,Accounts!$H:$H,"Jul 26") -> -6.2057 | G16: =SUMIFS(Accounts!$P:$P,Accounts!$A:$A,$A16,Accounts!$H:$H,"Aug 26") -> -5.7616 | H16: =F16-E16 -> -185.3879
A17: Calder Park Light Service Facility | B17: =SUMIFS(Accounts!$P:$P,Accounts!$A:$A,$A17,Accounts!$H:$H,"Mar 26") -> 0 | C17: =SUMIFS(Accounts!$P:$P,Accounts!$A:$A,$A17,Accounts!$H:$H,"Apr 26") -> 0 | D17: =SUMIFS(Accounts!$P:$P,Accounts!$A:$A,$A17,Accounts!$H:$H,"May 26") -> 0 | E17: =SUMIFS(Accounts!$P:$P,Accounts!$A:$A,$A17,Accounts!$H:$H,"Jun 26") -> 0 | F17: =SUMIFS(Accounts!$P:$P,Accounts!$A:$A,$A17,Accounts!$H:$H,"Jul 26") -> 0 | G17: =SUMIFS(Accounts!$P:$P,Accounts!$A:$A,$A17,Accounts!$H:$H,"Aug 26") -> 0 | H17: =F17-E17 -> 0
A18: Cardiff - Rail | B18: =SUMIFS(Accounts!$P:$P,Accounts!$A:$A,$A18,Accounts!$H:$H,"Mar 26") -> 86.9036 | C18: =SUMIFS(Accounts!$P:$P,Accounts!$A:$A,$A18,Accounts!$H:$H,"Apr 26") -> 78.3171 | D18: =SUMIFS(Accounts!$P:$P,Accounts!$A:$A,$A18,Accounts!$H:$H,"May 26") -> 86.5881 | E18: =SUMIFS(Accounts!$P:$P,Accounts!$A:$A,$A18,Accounts!$H:$H,"Jun 26") -> 86.814 | F18: =SUMIFS(Accounts!$P:$P,Accounts!$A:$A,$A18,Accounts!$H:$H,"Jul 26") -> 98.7423 | G18: =SUMIFS(Accounts!$P:$P,Accounts!$A:$A,$A18,Accounts!$H:$H,"Aug 26") -> 97.4596 | H18: =F18-E18 -> 11.9283
A19: HCMT - East Pakenham Depot | B19: =SUMIFS(Accounts!$P:$P,Accounts!$A:$A,$A19,Accounts!$H:$H,"Mar 26") -> 0 | C19: =SUMIFS(Accounts!$P:$P,Accounts!$A:$A,$A19,Accounts!$H:$H,"Apr 26") -> 0 | D19: =SUMIFS(Accounts!$P:$P,Accounts!$A:$A,$A19,Accounts!$H:$H,"May 26") -> 0 | E19: =SUMIFS(Accounts!$P:$P,Accounts!$A:$A,$A19,Accounts!$H:$H,"Jun 26") -> 0 | F19: =SUMIFS(Accounts!$P:$P,Accounts!$A:$A,$A19,Accounts!$H:$H,"Jul 26") -> 0 | G19: =SUMIFS(Accounts!$P:$P,Accounts!$A:$A,$A19,Accounts!$H:$H,"Aug 26") -> 0 | H19: =F19-E19 -> 0
A20: Maryborough | B20: =SUMIFS(Accounts!$P:$P,Accounts!$A:$A,$A20,Accounts!$H:$H,"Mar 26") -> 113.1038 | C20: =SUMIFS(Accounts!$P:$P,Accounts!$A:$A,$A20,Accounts!$H:$H,"Apr 26") -> 89.836 | D20: =SUMIFS(Accounts!$P:$P,Accounts!$A:$A,$A20,Accounts!$H:$H,"May 26") -> 98.47 | E20: =SUMIFS(Accounts!$P:$P,Accounts!$A:$A,$A20,Accounts!$H:$H,"Jun 26") -> 85.5732 | F20: =SUMIFS(Accounts!$P:$P,Accounts!$A:$A,$A20,Accounts!$H:$H,"Jul 26") -> -103.1334 | G20: =SUMIFS(Accounts!$P:$P,Accounts!$A:$A,$A20,Accounts!$H:$H,"Aug 26") -> -106.1848 | H20: =F20-E20 -> -188.7066
A21: N01 Anzac Square - Terrica Place | B21: =SUMIFS(Accounts!$P:$P,Accounts!$A:$A,$A21,Accounts!$H:$H,"Mar 26") -> 9.4304 | C21: =SUMIFS(Accounts!$P:$P,Accounts!$A:$A,$A21,Accounts!$H:$H,"Apr 26") -> 9.1306 | D21: =SUMIFS(Accounts!$P:$P,Accounts!$A:$A,$A21,Accounts!$H:$H,"May 26") -> 9.1792 | E21: =SUMIFS(Accounts!$P:$P,Accounts!$A:$A,$A21,Accounts!$H:$H,"Jun 26") -> 9.2234 | F21: =SUMIFS(Accounts!$P:$P,Accounts!$A:$A,$A21,Accounts!$H:$H,"Jul 26") -> 9.5024 | G21: =SUMIFS(Accounts!$P:$P,Accounts!$A:$A,$A21,Accounts!$H:$H,"Aug 26") -> 9.453 | H21: =F21-E21 -> 0.279
A22: Torbanlea - QTMP | B22: =SUMIFS(Accounts!$P:$P,Accounts!$A:$A,$A22,Accounts!$H:$H,"Mar 26") -> 69.8212 | C22: =SUMIFS(Accounts!$P:$P,Accounts!$A:$A,$A22,Accounts!$H:$H,"Apr 26") -> 79.2334 | D22: =SUMIFS(Accounts!$P:$P,Accounts!$A:$A,$A22,Accounts!$H:$H,"May 26") -> 93.578 | E22: =SUMIFS(Accounts!$P:$P,Accounts!$A:$A,$A22,Accounts!$H:$H,"Jun 26") -> 110.1842 | F22: =SUMIFS(Accounts!$P:$P,Accounts!$A:$A,$A22,Accounts!$H:$H,"Jul 26") -> 166.4961 | G22: =SUMIFS(Accounts!$P:$P,Accounts!$A:$A,$A22,Accounts!$H:$H,"Aug 26") -> 113.937 | H22: =F22-E22 -> 56.3119
A23: WTP Mobile Tech Hornsby | B23: =SUMIFS(Accounts!$P:$P,Accounts!$A:$A,$A23,Accounts!$H:$H,"Mar 26") -> 0.4169 | C23: =SUMIFS(Accounts!$P:$P,Accounts!$A:$A,$A23,Accounts!$H:$H,"Apr 26") -> 0.7184 | D23: =SUMIFS(Accounts!$P:$P,Accounts!$A:$A,$A23,Accounts!$H:$H,"May 26") -> 0.9051 | E23: =SUMIFS(Accounts!$P:$P,Accounts!$A:$A,$A23,Accounts!$H:$H,"Jun 26") -> 0.8759 | F23: =SUMIFS(Accounts!$P:$P,Accounts!$A:$A,$A23,Accounts!$H:$H,"Jul 26") -> 0.9051 | G23: =SUMIFS(Accounts!$P:$P,Accounts!$A:$A,$A23,Accounts!$H:$H,"Aug 26") -> 0.8719 | H23: =F23-E23 -> 0.0292
A24: Total RTS | B24: =SUM(B16:B23) -> 526.2495 | C24: =SUM(C16:C23) -> 444.7997 | D24: =SUM(D16:D23) -> 513.2089 | E24: =SUM(E16:E23) -> 471.8529 | F24: =SUM(F16:F23) -> 166.3068 | G24: =SUM(G16:G23) -> 109.7751 | H24: =SUM(H16:H23) -> -305.5461
A25: Red = a location netting below zero (over-credited). Amber = July more than 20 t above June.
A27: What I found
A28: 1. The three RTS virtual certificate accounts (Auburn x2, Maryborough QGGG000010) are calculating as set up: each mirrors its source kWh exactly in July and August, opened 1 Jul 26, no June row, and CO2e = kWh x factor. See Accounts, Check column.
A29: 2. Market-based electricity for RTS FELL in July, from 471.9 t (Jun) to 166.3 t, because those three accounts started crediting on 1 July. The July spike on the dashboard is not coming from the market-based electricity as it stands in the 6 Sep export.
A30: 3. Best fit for the 928 t: the dashboard was refreshed while the old CS Energy accounts at Maryborough (1003077, 1003082) and Torbanlea (1003571) still had no Replaced On and were accruing July (~165 + 7 + 110 = ~282 t) on top of the Engie actuals, and before the certificate accounts were linked. 739 (location-based) + 282 - 171 (HCMT deduction) + ~70-99 non-electricity = 920-950 t. The CS Energy accounts were closed at 30 Jun 26 between the 3 Sep and 5 Sep extracts, so a refresh should clear it. Scope 1 is not in this repo, so I cannot rule out a genuine July scope 1 movement - check gas and fuel for RTS if the refresh does not clear it.
A31: 4. All three certificate accounts are on 24-25 LGC factors (NSW -0.66, QLD -0.71) against electricity on 25-26 (0.64, 0.67), so each site nets slightly below zero: Auburn -6.2 t, Maryborough -11 t before the foundry issue. Needs the 25-26 LGC factors (already open).
A32: 5. Maryborough is over-credited by ~95 t a month. The certificate account copies the gross NMI figure (277,212 kWh) but the location nets out the CQMS foundry deduction (-141,380 kWh), so the location reports -103 t in July and -106 t in August. Either the virtual meter follows the net figure or the deduction stops - a Category Management call, and material to the RTS number.
A33: 6. Maryborough QGGG000320 has nothing recording since 30 Jun 26 (no Engie account yet). The interval meter reads 12,413 kWh in July and 10,262 in August, about 8 t and 7 t of uncounted location-based emissions.
A34: 7. Torbanlea - QTMP is a named exclusion, so no certificate account is correct. Its Engie account's first bill is 248,502 kWh for July, 51% above June's 164,454 and well above August's 170,055 - worth confirming the bill period with Engie before relying on July.
A35: 8. Two meter oddities at Auburn that do not affect the account-based emissions: the NEMMCO meter on 4103713125 reads exactly twice the account every month (as Wingfield does), and sub-meter DWR_MSB-5-LATHE reads 601,436 kWh in July against 3 kWh in June - about 385 t at the NSW factor, which is almost exactly the dashboard's June-to-July increase. If the dashboard reads meters as well as accounts, that is the spike.
A36: 9. Cardiff - Rail (CleanPeak, small market), HCMT, Calder Park, Anzac Square and Hornsby are not in the renewal register. HCMT and Calder Park net to zero through their Victorian 100% renewable deductions on the 25-26 factor, which is correct.

Sheet Accounts
A1: Location | B1: Account | C1: Account Style | D1: Data Type | E1: Supplier | F1: Opened On | G1: Replaced On | H1: Month | I1: kWh | J1: Actual % | K1: Accrued % | L1: Factor Name | M1: Factor (kg/kWh) | N1: Scope 2 reported (t) | O1: Other reported (t) | P1: Total reported (t) | Q1: Expected (t) = kWh x factor | R1: Variance (t) | S1: Factor vintage | T1: Source account | U1: Source kWh | V1: Mirror check | W1: Check
A2: Auburn | B2: 50002617957_4103713125 | C2: Electricity Large Market | D2: Electricity - Green [kWh] | E2: Origin | F2: 2020-07-01 | H2: Mar 26 | I2: 0 | L2: 77 - Electricity Green - 25-26 - New South Wales | M2: -0.64 | O2: 0 | Q2: =IF(M2="","",I2*M2/1000) -> 0 | R2: =IF(Q2="","",Q2-N(P2)) -> 0 | S2: =IF(L2="","",IF(ISNUMBER(SEARCH("25-26",L2)),"25-26",IF(ISNUMBER(SEARCH("24-25",L2)),"24-25","other"))) -> 25-26 | W2: =IF(AND(R2<>"",ABS(R2)>0.05),"CO2e not kWh x factor",IF(V2="kWh differs from source","Virtual meter not mirroring",IF(AND(D2="Certificates - Location [kWh]",S2="24-25"),"Certificate on 24-25 factor","OK"))) -> OK
A3: Auburn | B3: 50002617957_4103713125 | C3: Electricity Large Market | D3: Electricity - Green [kWh] | E3: Origin | F3: 2020-07-01 | H3: Apr 26 | I3: 0 | L3: 77 - Electricity Green - 25-26 - New South Wales | M3: -0.64 | O3: 0 | Q3: =IF(M3="","",I3*M3/1000) -> 0 | R3: =IF(Q3="","",Q3-N(P3)) -> 0 | S3: =IF(L3="","",IF(ISNUMBER(SEARCH("25-26",L3)),"25-26",IF(ISNUMBER(SEARCH("24-25",L3)),"24-25","other"))) -> 25-26 | W3: =IF(AND(R3<>"",ABS(R3)>0.05),"CO2e not kWh x factor",IF(V3="kWh differs from source","Virtual meter not mirroring",IF(AND(D3="Certificates - Location [kWh]",S3="24-25"),"Certificate on 24-25 factor","OK"))) -> OK
A4: Auburn | B4: 50002617957_4103713125 | C4: Electricity Large Market | D4: Electricity - Green [kWh] | E4: Origin | F4: 2020-07-01 | H4: May 26 | I4: 0 | L4: 77 - Electricity Green - 25-26 - New South Wales | M4: -0.64 | O4: 0 | Q4: =IF(M4="","",I4*M4/1000) -> 0 | R4: =IF(Q4="","",Q4-N(P4)) -> 0 | S4: =IF(L4="","",IF(ISNUMBER(SEARCH("25-26",L4)),"25-26",IF(ISNUMBER(SEARCH("24-25",L4)),"24-25","other"))) -> 25-26 | W4: =IF(AND(R4<>"",ABS(R4)>0.05),"CO2e not kWh x factor",IF(V4="kWh differs from source","Virtual meter not mirroring",IF(AND(D4="Certificates - Location [kWh]",S4="24-25"),"Certificate on 24-25 factor","OK"))) -> OK
A5: Auburn | B5: 50002617957_4103713125 | C5: Electricity Large Market | D5: Electricity - Green [kWh] | E5: Origin | F5: 2020-07-01 | H5: Jun 26 | I5: 0 | L5: 77 - Electricity Green - 25-26 - New South Wales | M5: -0.64 | O5: 0 | Q5: =IF(M5="","",I5*M5/1000) -> 0 | R5: =IF(Q5="","",Q5-N(P5)) -> 0 | S5: =IF(L5="","",IF(ISNUMBER(SEARCH("25-26",L5)),"25-26",IF(ISNUMBER(SEARCH("24-25",L5)),"24-25","other"))) -> 25-26 | W5: =IF(AND(R5<>"",ABS(R5)>0.05),"CO2e not kWh x factor",IF(V5="kWh differs from source","Virtual meter not mirroring",IF(AND(D5="Certificates - Location [kWh]",S5="24-25"),"Certificate on 24-25 factor","OK"))) -> OK
A6: Auburn | B6: 50002617957_4103713125 | C6: Electricity Large Market | D6: Electricity - Green [kWh] | E6: Origin | F6: 2020-07-01 | H6: Jul 26 | I6: 0 | L6: 77 - Electricity Green - 25-26 - New South Wales | M6: -0.64 | O6: 0 | Q6: =IF(M6="","",I6*M6/1000) -> 0 | R6: =IF(Q6="","",Q6-N(P6)) -> 0 | S6: =IF(L6="","",IF(ISNUMBER(SEARCH("25-26",L6)),"25-26",IF(ISNUMBER(SEARCH("24-25",L6)),"24-25","other"))) -> 25-26 | W6: =IF(AND(R6<>"",ABS(R6)>0.05),"CO2e not kWh x factor",IF(V6="kWh differs from source","Virtual meter not mirroring",IF(AND(D6="Certificates - Location [kWh]",S6="24-25"),"Certificate on 24-25 factor","OK"))) -> OK
A7: Auburn | B7: 50002617957_4103713125 | C7: Electricity Large Market | D7: Electricity - Green [kWh] | E7: Origin | F7: 2020-07-01 | H7: Aug 26 | I7: 0 | L7: 77 - Electricity Green - 25-26 - New South Wales | M7: -0.64 | O7: 0 | Q7: =IF(M7="","",I7*M7/1000) -> 0 | R7: =IF(Q7="","",Q7-N(P7)) -> 0 | S7: =IF(L7="","",IF(ISNUMBER(SEARCH("25-26",L7)),"25-26",IF(ISNUMBER(SEARCH("24-25",L7)),"24-25","other"))) -> 25-26 | W7: =IF(AND(R7<>"",ABS(R7)>0.05),"CO2e not kWh x factor",IF(V7="kWh differs from source","Virtual meter not mirroring",IF(AND(D7="Certificates - Location [kWh]",S7="24-25"),"Certificate on 24-25 factor","OK"))) -> OK
A8: Auburn | B8: 50002617957_4103713125 | C8: Electricity Large Market | D8: Electricity [kWh] | E8: Origin | F8: 2020-07-01 | H8: Mar 26 | I8: 180656.1 | J8: 100 | K8: 0 | L8: 77 - Electricity - 25-26 - New South Wales | M8: 0.64 | N8: 115.6199 | P8: 115.6199 | Q8: =IF(M8="","",I8*M8/1000) -> 115.6199 | R8: =IF(Q8="","",Q8-N(P8)) -> 4e-06 | S8: =IF(L8="","",IF(ISNUMBER(SEARCH("25-26",L8)),"25-26",IF(ISNUMBER(SEARCH("24-25",L8)),"24-25","other"))) -> 25-26 | W8: =IF(AND(R8<>"",ABS(R8)>0.05),"CO2e not kWh x factor",IF(V8="kWh differs from source","Virtual meter not mirroring",IF(AND(D8="Certificates - Location [kWh]",S8="24-25"),"Certificate on 24-25 factor","OK"))) -> OK
A9: Auburn | B9: 50002617957_4103713125 | C9: Electricity Large Market | D9: Electricity [kWh] | E9: Origin | F9: 2020-07-01 | H9: Apr 26 | I9: 192993.3 | J9: 100 | K9: 0 | L9: 77 - Electricity - 25-26 - New South Wales | M9: 0.64 | N9: 123.5157 | P9: 123.5157 | Q9: =IF(M9="","",I9*M9/1000) -> 123.51571 | R9: =IF(Q9="","",Q9-N(P9)) -> 1.2e-05 | S9: =IF(L9="","",IF(ISNUMBER(SEARCH("25-26",L9)),"25-26",IF(ISNUMBER(SEARCH("24-25",L9)),"24-25","other"))) -> 25-26 | W9: =IF(AND(R9<>"",ABS(R9)>0.05),"CO2e not kWh x factor",IF(V9="kWh differs from source","Virtual meter not mirroring",IF(AND(D9="Certificates - Location [kWh]",S9="24-25"),"Certificate on 24-25 factor","OK"))) -> OK
A10: Auburn | B10: 50002617957_4103713125 | C10: Electricity Large Market | D10: Electricity [kWh] | E10: Origin | F10: 2020-07-01 | H10: May 26 | I10: 347500.3 | J10: 100 | K10: 0 | L10: 77 - Electricity - 25-26 - New South Wales | M10: 0.64 | N10: 222.4002 | P10: 222.4002 | Q10: =IF(M10="","",I10*M10/1000) -> 222.40019 | R10: =IF(Q10="","",Q10-N(P10)) -> -8e-06 | S10: =IF(L10="","",IF(ISNUMBER(SEARCH("25-26",L10)),"25-26",IF(ISNUMBER(SEARCH("24-25",L10)),"24-25","other"))) -> 25-26 | W10: =IF(AND(R10<>"",ABS(R10)>0.05),"CO2e not kWh x factor",IF(V10="kWh differs from source","Virtual meter not mirroring",IF(AND(D10="Certificates - Location [kWh]",S10="24-25"),"Certificate on 24-25 factor","OK"))) -> OK
A11: Auburn | B11: 50002617957_4103713125 | C11: Electricity Large Market | D11: Electricity [kWh] | E11: Origin | F11: 2020-07-01 | H11: Jun 26 | I11: 272068.2 | J11: 100 | K11: 0 | L11: 77 - Electricity - 25-26 - New South Wales | M11: 0.64 | N11: 174.1236 | P11: 174.1236 | Q11: =IF(M11="","",I11*M11/1000) -> 174.12365 | R11: =IF(Q11="","",Q11-N(P11)) -> 4.8e-05 | S11: =IF(L11="","",IF(ISNUMBER(SEARCH("25-26",L11)),"25-26",IF(ISNUMBER(SEARCH("24-25",L11)),"24-25","other"))) -> 25-26 | W11: =IF(AND(R11<>"",ABS(R11)>0.05),"CO2e not kWh x factor",IF(V11="kWh differs from source","Virtual meter not mirroring",IF(AND(D11="Certificates - Location [kWh]",S11="24-25"),"Certificate on 24-25 factor","OK"))) -> OK
A12: Auburn | B12: 50002617957_4103713125 | C12: Electricity Large Market | D12: Electricity [kWh] | E12: Origin | F12: 2020-07-01 | H12: Jul 26 | I12: 283780.3 | J12: 100 | K12: 0 | L12: 77 - Electricity - 25-26 - New South Wales | M12: 0.64 | N12: 181.6194 | P12: 181.6194 | Q12: =IF(M12="","",I12*M12/1000) -> 181.61939 | R12: =IF(Q12="","",Q12-N(P12)) -> -8e-06 | S12: =IF(L12="","",IF(ISNUMBER(SEARCH("25-26",L12)),"25-26",IF(ISNUMBER(SEARCH("24-25",L12)),"24-25","other"))) -> 25-26 | W12: =IF(AND(R12<>"",ABS(R12)>0.05),"CO2e not kWh x factor",IF(V12="kWh differs from source","Virtual meter not mirroring",IF(AND(D12="Certificates - Location [kWh]",S12="24-25"),"Certificate on 24-25 factor","OK"))) -> OK
A13: Auburn | B13: 50002617957_4103713125 | C13: Electricity Large Market | D13: Electricity [kWh] | E13: Origin | F13: 2020-07-01 | H13: Aug 26 | I13: 260437 | J13: 100 | K13: 0 | L13: 77 - Electricity - 25-26 - New South Wales | M13: 0.64 | N13: 166.6797 | P13: 166.6797 | Q13: =IF(M13="","",I13*M13/1000) -> 166.67968 | R13: =IF(Q13="","",Q13-N(P13)) -> -2e-05 | S13: =IF(L13="","",IF(ISNUMBER(SEARCH("25-26",L13)),"25-26",IF(ISNUMBER(SEARCH("24-25",L13)),"24-25","other"))) -> 25-26 | W13: =IF(AND(R13<>"",ABS(R13)>0.05),"CO2e not kWh x factor",IF(V13="kWh differs from source","Virtual meter not mirroring",IF(AND(D13="Certificates - Location [kWh]",S13="24-25"),"Certificate on 24-25 factor","OK"))) -> OK
A14: Auburn | B14: 50002617957_4103713125_CERTS | C14: Certificates - Location - kWh | D14: Certificates - Location [kWh] | E14: LGC Virtual Account | F14: 2026-07-01 | H14: Jul 26 | I14: 283780.3 | J14: 100 | K14: 0 | L14: LGCs NSW 24-25 | M14: -0.66 | O14: -187.295 | P14: -187.295 | Q14: =IF(M14="","",I14*M14/1000) -> -187.295 | R14: =IF(Q14="","",Q14-N(P14)) -> 2e-06 | S14: =IF(L14="","",IF(ISNUMBER(SEARCH("25-26",L14)),"25-26",IF(ISNUMBER(SEARCH("24-25",L14)),"24-25","other"))) -> 24-25 | T14: 50002617957_4103713125 | U14: =SUMIFS($I:$I,$B:$B,T14,$H:$H,H14,$D:$D,"Electricity [kWh]") -> 283780.3 | V14: =IF(ABS(I14-U14)<0.5,"Mirrors source","kWh differs from source") -> Mirrors source | W14: =IF(AND(R14<>"",ABS(R14)>0.05),"CO2e not kWh x factor",IF(V14="kWh differs from source","Virtual meter not mirroring",IF(AND(D14="Certificates - Location [kWh]",S14="24-25"),"Certificate on 24-25 factor","OK"))) -> Certificate on 24-25 factor
A15: Auburn | B15: 50002617957_4103713125_CERTS | C15: Certificates - Location - kWh | D15: Certificates - Location [kWh] | E15: LGC Virtual Account | F15: 2026-07-01 | H15: Aug 26 | I15: 260437 | J15: 100 | K15: 0 | L15: LGCs NSW 24-25 | M15: -0.66 | O15: -171.8884 | P15: -171.8884 | Q15: =IF(M15="","",I15*M15/1000) -> -171.88842 | R15: =IF(Q15="","",Q15-N(P15)) -> -2e-05 | S15: =IF(L15="","",IF(ISNUMBER(SEARCH("25-26",L15)),"25-26",IF(ISNUMBER(SEARCH("24-25",L15)),"24-25","other"))) -> 24-25 | T15: 50002617957_4103713125 | U15: =SUMIFS($I:$I,$B:$B,T15,$H:$H,H15,$D:$D,"Electricity [kWh]") -> 260437 | V15: =IF(ABS(I15-U15)<0.5,"Mirrors source","kWh differs from source") -> Mirrors source | W15: =IF(AND(R15<>"",ABS(R15)>0.05),"CO2e not kWh x factor",IF(V15="kWh differs from source","Virtual meter not mirroring",IF(AND(D15="Certificates - Location [kWh]",S15="24-25"),"Certificate on 24-25 factor","OK"))) -> Certificate on 24-25 factor
A16: Auburn | B16: 50002617965_4103711576 | C16: Electricity Large Market | D16: Electricity - Green [kWh] | E16: Origin | F16: 2020-07-01 | H16: Mar 26 | I16: 0 | L16: 77 - Electricity Green - 25-26 - New South Wales | M16: -0.64 | O16: 0 | Q16: =IF(M16="","",I16*M16/1000) -> 0 | R16: =IF(Q16="","",Q16-N(P16)) -> 0 | S16: =IF(L16="","",IF(ISNUMBER(SEARCH("25-26",L16)),"25-26",IF(ISNUMBER(SEARCH("24-25",L16)),"24-25","other"))) -> 25-26 | W16: =IF(AND(R16<>"",ABS(R16)>0.05),"CO2e not kWh x factor",IF(V16="kWh differs from source","Virtual meter not mirroring",IF(AND(D16="Certificates - Location [kWh]",S16="24-25"),"Certificate on 24-25 factor","OK"))) -> OK
A17: Auburn | B17: 50002617965_4103711576 | C17: Electricity Large Market | D17: Electricity - Green [kWh] | E17: Origin | F17: 2020-07-01 | H17: Apr 26 | I17: 0 | L17: 77 - Electricity Green - 25-26 - New South Wales | M17: -0.64 | O17: 0 | Q17: =IF(M17="","",I17*M17/1000) -> 0 | R17: =IF(Q17="","",Q17-N(P17)) -> 0 | S17: =IF(L17="","",IF(ISNUMBER(SEARCH("25-26",L17)),"25-26",IF(ISNUMBER(SEARCH("24-25",L17)),"24-25","other"))) -> 25-26 | W17: =IF(AND(R17<>"",ABS(R17)>0.05),"CO2e not kWh x factor",IF(V17="kWh differs from source","Virtual meter not mirroring",IF(AND(D17="Certificates - Location [kWh]",S17="24-25"),"Certificate on 24-25 factor","OK"))) -> OK
A18: Auburn | B18: 50002617965_4103711576 | C18: Electricity Large Market | D18: Electricity - Green [kWh] | E18: Origin | F18: 2020-07-01 | H18: May 26 | I18: 0 | L18: 77 - Electricity Green - 25-26 - New South Wales | M18: -0.64 | O18: 0 | Q18: =IF(M18="","",I18*M18/1000) -> 0 | R18: =IF(Q18="","",Q18-N(P18)) -> 0 | S18: =IF(L18="","",IF(ISNUMBER(SEARCH("25-26",L18)),"25-26",IF(ISNUMBER(SEARCH("24-25",L18)),"24-25","other"))) -> 25-26 | W18: =IF(AND(R18<>"",ABS(R18)>0.05),"CO2e not kWh x factor",IF(V18="kWh differs from source","Virtual meter not mirroring",IF(AND(D18="Certificates - Location [kWh]",S18="24-25"),"Certificate on 24-25 factor","OK"))) -> OK
A19: Auburn | B19: 50002617965_4103711576 | C19: Electricity Large Market | D19: Electricity - Green [kWh] | E19: Origin | F19: 2020-07-01 | H19: Jun 26 | I19: 0 | L19: 77 - Electricity Green - 25-26 - New South Wales | M19: -0.64 | O19: 0 | Q19: =IF(M19="","",I19*M19/1000) -> 0 | R19: =IF(Q19="","",Q19-N(P19)) -> 0 | S19: =IF(L19="","",IF(ISNUMBER(SEARCH("25-26",L19)),"25-26",IF(ISNUMBER(SEARCH("24-25",L19)),"24-25","other"))) -> 25-26 | W19: =IF(AND(R19<>"",ABS(R19)>0.05),"CO2e not kWh x factor",IF(V19="kWh differs from source","Virtual meter not mirroring",IF(AND(D19="Certificates - Location [kWh]",S19="24-25"),"Certificate on 24-25 factor","OK"))) -> OK
A20: Auburn | B20: 50002617965_4103711576 | C20: Electricity Large Market | D20: Electricity - Green [kWh] | E20: Origin | F20: 2020-07-01 | H20: Jul 26 | I20: 0 | L20: 77 - Electricity Green - 25-26 - New South Wales | M20: -0.64 | O20: 0 | Q20: =IF(M20="","",I20*M20/1000) -> 0 | R20: =IF(Q20="","",Q20-N(P20)) -> 0 | S20: =IF(L20="","",IF(ISNUMBER(SEARCH("25-26",L20)),"25-26",IF(ISNUMBER(SEARCH("24-25",L20)),"24-25","other"))) -> 25-26 | W20: =IF(AND(R20<>"",ABS(R20)>0.05),"CO2e not kWh x factor",IF(V20="kWh differs from source","Virtual meter not mirroring",IF(AND(D20="Certificates - Location [kWh]",S20="24-25"),"Certificate on 24-25 factor","OK"))) -> OK
A21: Auburn | B21: 50002617965_4103711576 | C21: Electricity Large Market | D21: Electricity - Green [kWh] | E21: Origin | F21: 2020-07-01 | H21: Aug 26 | I21: 0 | L21: 77 - Electricity Green - 25-26 - New South Wales | M21: -0.64 | O21: 0 | Q21: =IF(M21="","",I21*M21/1000) -> 0 | R21: =IF(Q21="","",Q21-N(P21)) -> 0 | S21: =IF(L21="","",IF(ISNUMBER(SEARCH("25-26",L21)),"25-26",IF(ISNUMBER(SEARCH("24-25",L21)),"24-25","other"))) -> 25-26 | W21: =IF(AND(R21<>"",ABS(R21)>0.05),"CO2e not kWh x factor",IF(V21="kWh differs from source","Virtual meter not mirroring",IF(AND(D21="Certificates - Location [kWh]",S21="24-25"),"Certificate on 24-25 factor","OK"))) -> OK
A22: Auburn | B22: 50002617965_4103711576 | C22: Electricity Large Market | D22: Electricity [kWh] | E22: Origin | F22: 2020-07-01 | H22: Mar 26 | I22: 204615.2 | J22: 100 | K22: 0 | L22: 77 - Electricity - 25-26 - New South Wales | M22: 0.64 | N22: 130.9537 | P22: 130.9537 | Q22: =IF(M22="","",I22*M22/1000) -> 130.95373 | R22: =IF(Q22="","",Q22-N(P22)) -> 2.8e-05 | S22: =IF(L22="","",IF(ISNUMBER(SEARCH("25-26",L22)),"25-26",IF(ISNUMBER(SEARCH("24-25",L22)),"24-25","other"))) -> 25-26 | W22: =IF(AND(R22<>"",ABS(R22)>0.05),"CO2e not kWh x factor",IF(V22="kWh differs from source","Virtual meter not mirroring",IF(AND(D22="Certificates - Location [kWh]",S22="24-25"),"Certificate on 24-25 factor","OK"))) -> OK
A23: Auburn | B23: 50002617965_4103711576 | C23: Electricity Large Market | D23: Electricity [kWh] | E23: Origin | F23: 2020-07-01 | H23: Apr 26 | I23: 100075.85 | J23: 100 | K23: 0 | L23: 77 - Electricity - 25-26 - New South Wales | M23: 0.64 | N23: 64.0485 | P23: 64.0485 | Q23: =IF(M23="","",I23*M23/1000) -> 64.048544 | R23: =IF(Q23="","",Q23-N(P23)) -> 4.4e-05 | S23: =IF(L23="","",IF(ISNUMBER(SEARCH("25-26",L23)),"25-26",IF(ISNUMBER(SEARCH("24-25",L23)),"24-25","other"))) -> 25-26 | W23: =IF(AND(R23<>"",ABS(R23)>0.05),"CO2e not kWh x factor",IF(V23="kWh differs from source","Virtual meter not mirroring",IF(AND(D23="Certificates - Location [kWh]",S23="24-25"),"Certificate on 24-25 factor","OK"))) -> OK
A24: Auburn | B24: 50002617965_4103711576 | C24: Electricity Large Market | D24: Electricity [kWh] | E24: Origin | F24: 2020-07-01 | H24: May 26 | I24: 3263 | J24: 100 | K24: 0 | L24: 77 - Electricity - 25-26 - New South Wales | M24: 0.64 | N24: 2.0883 | P24: 2.0883 | Q24: =IF(M24="","",I24*M24/1000) -> 2.08832 | R24: =IF(Q24="","",Q24-N(P24)) -> 2e-05 | S24: =IF(L24="","",IF(ISNUMBER(SEARCH("25-26",L24)),"25-26",IF(ISNUMBER(SEARCH("24-25",L24)),"24-25","other"))) -> 25-26 | W24: =IF(AND(R24<>"",ABS(R24)>0.05),"CO2e not kWh x factor",IF(V24="kWh differs from source","Virtual meter not mirroring",IF(AND(D24="Certificates - Location [kWh]",S24="24-25"),"Certificate on 24-25 factor","OK"))) -> OK
A25: Auburn | B25: 50002617965_4103711576 | C25: Electricity Large Market | D25: Electricity [kWh] | E25: Origin | F25: 2020-07-01 | H25: Jun 26 | I25: 7904.1 | J25: 100 | K25: 0 | L25: 77 - Electricity - 25-26 - New South Wales | M25: 0.64 | N25: 5.0586 | P25: 5.0586 | Q25: =IF(M25="","",I25*M25/1000) -> 5.058624 | R25: =IF(Q25="","",Q25-N(P25)) -> 2.4e-05 | S25: =IF(L25="","",IF(ISNUMBER(SEARCH("25-26",L25)),"25-26",IF(ISNUMBER(SEARCH("24-25",L25)),"24-25","other"))) -> 25-26 | W25: =IF(AND(R25<>"",ABS(R25)>0.05),"CO2e not kWh x factor",IF(V25="kWh differs from source","Virtual meter not mirroring",IF(AND(D25="Certificates - Location [kWh]",S25="24-25"),"Certificate on 24-25 factor","OK"))) -> OK
A26: Auburn | B26: 50002617965_4103711576 | C26: Electricity Large Market | D26: Electricity [kWh] | E26: Origin | F26: 2020-07-01 | H26: Jul 26 | I26: 26500.7 | J26: 100 | K26: 0 | L26: 77 - Electricity - 25-26 - New South Wales | M26: 0.64 | N26: 16.9604 | P26: 16.9604 | Q26: =IF(M26="","",I26*M26/1000) -> 16.960448 | R26: =IF(Q26="","",Q26-N(P26)) -> 4.8e-05 | S26: =IF(L26="","",IF(ISNUMBER(SEARCH("25-26",L26)),"25-26",IF(ISNUMBER(SEARCH("24-25",L26)),"24-25","other"))) -> 25-26 | W26: =IF(AND(R26<>"",ABS(R26)>0.05),"CO2e not kWh x factor",IF(V26="kWh differs from source","Virtual meter not mirroring",IF(AND(D26="Certificates - Location [kWh]",S26="24-25"),"Certificate on 24-25 factor","OK"))) -> OK
A27: Auburn | B27: 50002617965_4103711576 | C27: Electricity Large Market | D27: Electricity [kWh] | E27: Origin | F27: 2020-07-01 | H27: Aug 26 | I27: 27646.5 | J27: 100 | K27: 0 | L27: 77 - Electricity - 25-26 - New South Wales | M27: 0.64 | N27: 17.6938 | P27: 17.6938 | Q27: =IF(M27="","",I27*M27/1000) -> 17.69376 | R27: =IF(Q27="","",Q27-N(P27)) -> -4e-05 | S27: =IF(L27="","",IF(ISNUMBER(SEARCH("25-26",L27)),"25-26",IF(ISNUMBER(SEARCH("24-25",L27)),"24-25","other"))) -> 25-26 | W27: =IF(AND(R27<>"",ABS(R27)>0.05),"CO2e not kWh x factor",IF(V27="kWh differs from source","Virtual meter not mirroring",IF(AND(D27="Certificates - Location [kWh]",S27="24-25"),"Certificate on 24-25 factor","OK"))) -> OK
A28: Auburn | B28: 50002617965_4103711576_CERTS | C28: Certificates - Location - kWh | D28: Certificates - Location [kWh] | E28: LGC Virtual Account | F28: 2026-07-01 | H28: Jul 26 | I28: 26500.7 | J28: 100 | K28: 0 | L28: LGCs NSW 24-25 | M28: -0.66 | O28: -17.4905 | P28: -17.4905 | Q28: =IF(M28="","",I28*M28/1000) -> -17.490462 | R28: =IF(Q28="","",Q28-N(P28)) -> 3.8e-05 | S28: =IF(L28="","",IF(ISNUMBER(SEARCH("25-26",L28)),"25-26",IF(ISNUMBER(SEARCH("24-25",L28)),"24-25","other"))) -> 24-25 | T28: 50002617965_4103711576 | U28: =SUMIFS($I:$I,$B:$B,T28,$H:$H,H28,$D:$D,"Electricity [kWh]") -> 26500.7 | V28: =IF(ABS(I28-U28)<0.5,"Mirrors source","kWh differs from source") -> Mirrors source | W28: =IF(AND(R28<>"",ABS(R28)>0.05),"CO2e not kWh x factor",IF(V28="kWh differs from source","Virtual meter not mirroring",IF(AND(D28="Certificates - Location [kWh]",S28="24-25"),"Certificate on 24-25 factor","OK"))) -> Certificate on 24-25 factor
A29: Auburn | B29: 50002617965_4103711576_CERTS | C29: Certificates - Location - kWh | D29: Certificates - Location [kWh] | E29: LGC Virtual Account | F29: 2026-07-01 | H29: Aug 26 | I29: 27646.5 | J29: 100 | K29: 0 | L29: LGCs NSW 24-25 | M29: -0.66 | O29: -18.2467 | P29: -18.2467 | Q29: =IF(M29="","",I29*M29/1000) -> -18.24669 | R29: =IF(Q29="","",Q29-N(P29)) -> 1e-05 | S29: =IF(L29="","",IF(ISNUMBER(SEARCH("25-26",L29)),"25-26",IF(ISNUMBER(SEARCH("24-25",L29)),"24-25","other"))) -> 24-25 | T29: 50002617965_4103711576 | U29: =SUMIFS($I:$I,$B:$B,T29,$H:$H,H29,$D:$D,"Electricity [kWh]") -> 27646.5 | V29: =IF(ABS(I29-U29)<0.5,"Mirrors source","kWh differs from source") -> Mirrors source | W29: =IF(AND(R29<>"",ABS(R29)>0.05),"CO2e not kWh x factor",IF(V29="kWh differs from source","Virtual meter not mirroring",IF(AND(D29="Certificates - Location [kWh]",S29="24-25"),"Certificate on 24-25 factor","OK"))) -> Certificate on 24-25 factor
A30: Calder Park Light Service Facility | B30: Calder Park 100% Renewable Electricity | C30: Certificates - Location - kWh | D30: Certificates - Location [kWh] | E30: SEC VIC | F30: 2025-07-01 | H30: Mar 26 | I30: 66.1 | J30: 100 | K30: 0 | L30: LGCs Victoria 25-26 | M30: -0.78 | O30: -0.0516 | P30: -0.0516 | Q30: =IF(M30="","",I30*M30/1000) -> -0.051558 | R30: =IF(Q30="","",Q30-N(P30)) -> 4.2e-05 | S30: =IF(L30="","",IF(ISNUMBER(SEARCH("25-26",L30)),"25-26",IF(ISNUMBER(SEARCH("24-25",L30)),"24-25","other"))) -> 25-26 | W30: =IF(AND(R30<>"",ABS(R30)>0.05),"CO2e not kWh x factor",IF(V30="kWh differs from source","Virtual meter not mirroring",IF(AND(D30="Certificates - Location [kWh]",S30="24-25"),"Certificate on 24-25 factor","OK"))) -> OK
A31: Calder Park Light Service Facility | B31: Calder Park 100% Renewable Electricity | C31: Certificates - Location - kWh | D31: Certificates - Location [kWh] | E31: SEC VIC | F31: 2025-07-01 | H31: Apr 26 | I31: 140.3 | J31: 100 | K31: 0 | L31: LGCs Victoria 25-26 | M31: -0.78 | O31: -0.1094 | P31: -0.1094 | Q31: =IF(M31="","",I31*M31/1000) -> -0.109434 | R31: =IF(Q31="","",Q31-N(P31)) -> -3.4e-05 | S31: =IF(L31="","",IF(ISNUMBER(SEARCH("25-26",L31)),"25-26",IF(ISNUMBER(SEARCH("24-25",L31)),"24-25","other"))) -> 25-26 | W31: =IF(AND(R31<>"",ABS(R31)>0.05),"CO2e not kWh x factor",IF(V31="kWh differs from source","Virtual meter not mirroring",IF(AND(D31="Certificates - Location [kWh]",S31="24-25"),"Certificate on 24-25 factor","OK"))) -> OK
A32: Calder Park Light Service Facility | B32: Calder Park 100% Renewable Electricity | C32: Certificates - Location - kWh | D32: Certificates - Location [kWh] | E32: SEC VIC | F32: 2025-07-01 | H32: May 26 | I32: 18.7 | J32: 100 | K32: 0 | L32: LGCs Victoria 25-26 | M32: -0.78 | O32: -0.0146 | P32: -0.0146 | Q32: =IF(M32="","",I32*M32/1000) -> -0.014586 | R32: =IF(Q32="","",Q32-N(P32)) -> 1.4e-05 | S32: =IF(L32="","",IF(ISNUMBER(SEARCH("25-26",L32)),"25-26",IF(ISNUMBER(SEARCH("24-25",L32)),"24-25","other"))) -> 25-26 | W32: =IF(AND(R32<>"",ABS(R32)>0.05),"CO2e not kWh x factor",IF(V32="kWh differs from source","Virtual meter not mirroring",IF(AND(D32="Certificates - Location [kWh]",S32="24-25"),"Certificate on 24-25 factor","OK"))) -> OK
A33: Calder Park Light Service Facility | B33: Calder Park 100% Renewable Electricity | C33: Certificates - Location - kWh | D33: Certificates - Location [kWh] | E33: SEC VIC | F33: 2025-07-01 | H33: Jun 26 | I33: 199.9 | J33: 100 | K33: 0 | L33: LGCs Victoria 25-26 | M33: -0.78 | O33: -0.1559 | P33: -0.1559 | Q33: =IF(M33="","",I33*M33/1000) -> -0.155922 | R33: =IF(Q33="","",Q33-N(P33)) -> -2.2e-05 | S33: =IF(L33="","",IF(ISNUMBER(SEARCH("25-26",L33)),"25-26",IF(ISNUMBER(SEARCH("24-25",L33)),"24-25","other"))) -> 25-26 | W33: =IF(AND(R33<>"",ABS(R33)>0.05),"CO2e not kWh x factor",IF(V33="kWh differs from source","Virtual meter not mirroring",IF(AND(D33="Certificates - Location [kWh]",S33="24-25"),"Certificate on 24-25 factor","OK"))) -> OK
A34: Calder Park Light Service Facility | B34: Calder Park 100% Renewable Electricity | C34: Certificates - Location - kWh | D34: Certificates - Location [kWh] | E34: SEC VIC | F34: 2025-07-01 | H34: Jul 26 | I34: 206.5623 | J34: 0 | K34: 0 | L34: LGCs Victoria 25-26 | M34: -0.78 | O34: -0.1611 | P34: -0.1611 | Q34: =IF(M34="","",I34*M34/1000) -> -0.16111859 | R34: =IF(Q34="","",Q34-N(P34)) -> -1.8594e-05 | S34: =IF(L34="","",IF(ISNUMBER(SEARCH("25-26",L34)),"25-26",IF(ISNUMBER(SEARCH("24-25",L34)),"24-25","other"))) -> 25-26 | W34: =IF(AND(R34<>"",ABS(R34)>0.05),"CO2e not kWh x factor",IF(V34="kWh differs from source","Virtual meter not mirroring",IF(AND(D34="Certificates - Location [kWh]",S34="24-25"),"Certificate on 24-25 factor","OK"))) -> OK
A35: Calder Park Light Service Facility | B35: Calder Park 100% Renewable Electricity | C35: Certificates - Location - kWh | D35: Certificates - Location [kWh] | E35: SEC VIC | F35: 2025-07-01 | H35: Aug 26 | I35: 206.5623 | J35: 0 | K35: 0 | L35: LGCs Victoria 25-26 | M35: -0.78 | O35: -0.1611 | P35: -0.1611 | Q35: =IF(M35="","",I35*M35/1000) -> -0.16111859 | R35: =IF(Q35="","",Q35-N(P35)) -> -1.8594e-05 | S35: =IF(L35="","",IF(ISNUMBER(SEARCH("25-26",L35)),"25-26",IF(ISNUMBER(SEARCH("24-25",L35)),"24-25","other"))) -> 25-26 | W35: =IF(AND(R35<>"",ABS(R35)>0.05),"CO2e not kWh x factor",IF(V35="kWh differs from source","Virtual meter not mirroring",IF(AND(D35="Certificates - Location [kWh]",S35="24-25"),"Certificate on 24-25 factor","OK"))) -> OK
A36: Calder Park Light Service Facility | B36: Grid Electricity | C36: Electricity – purchased from grid [kWh] | D36: Electricity [kWh] | E36: Downer | F36: 2026-01-01 | H36: Mar 26 | I36: 66.1 | J36: 100 | K36: 0 | L36: 78 - Electricity - 25-26 - Victoria | M36: 0.78 | N36: 0.0516 | P36: 0.0516 | Q36: =IF(M36="","",I36*M36/1000) -> 0.051558 | R36: =IF(Q36="","",Q36-N(P36)) -> -4.2e-05 | S36: =IF(L36="","",IF(ISNUMBER(SEARCH("25-26",L36)),"25-26",IF(ISNUMBER(SEARCH("24-25",L36)),"24-25","other"))) -> 25-26 | W36: =IF(AND(R36<>"",ABS(R36)>0.05),"CO2e not kWh x factor",IF(V36="kWh differs from source","Virtual meter not mirroring",IF(AND(D36="Certificates - Location [kWh]",S36="24-25"),"Certificate on 24-25 factor","OK"))) -> OK
A37: Calder Park Light Service Facility | B37: Grid Electricity | C37: Electricity – purchased from grid [kWh] | D37: Electricity [kWh] | E37: Downer | F37: 2026-01-01 | H37: Apr 26 | I37: 140.3 | J37: 100 | K37: 0 | L37: 78 - Electricity - 25-26 - Victoria | M37: 0.78 | N37: 0.1094 | P37: 0.1094 | Q37: =IF(M37="","",I37*M37/1000) -> 0.109434 | R37: =IF(Q37="","",Q37-N(P37)) -> 3.4e-05 | S37: =IF(L37="","",IF(ISNUMBER(SEARCH("25-26",L37)),"25-26",IF(ISNUMBER(SEARCH("24-25",L37)),"24-25","other"))) -> 25-26 | W37: =IF(AND(R37<>"",ABS(R37)>0.05),"CO2e not kWh x factor",IF(V37="kWh differs from source","Virtual meter not mirroring",IF(AND(D37="Certificates - Location [kWh]",S37="24-25"),"Certificate on 24-25 factor","OK"))) -> OK
A38: Calder Park Light Service Facility | B38: Grid Electricity | C38: Electricity – purchased from grid [kWh] | D38: Electricity [kWh] | E38: Downer | F38: 2026-01-01 | H38: May 26 | I38: 18.7 | J38: 100 | K38: 0 | L38: 78 - Electricity - 25-26 - Victoria | M38: 0.78 | N38: 0.0146 | P38: 0.0146 | Q38: =IF(M38="","",I38*M38/1000) -> 0.014586 | R38: =IF(Q38="","",Q38-N(P38)) -> -1.4e-05 | S38: =IF(L38="","",IF(ISNUMBER(SEARCH("25-26",L38)),"25-26",IF(ISNUMBER(SEARCH("24-25",L38)),"24-25","other"))) -> 25-26 | W38: =IF(AND(R38<>"",ABS(R38)>0.05),"CO2e not kWh x factor",IF(V38="kWh differs from source","Virtual meter not mirroring",IF(AND(D38="Certificates - Location [kWh]",S38="24-25"),"Certificate on 24-25 factor","OK"))) -> OK
A39: Calder Park Light Service Facility | B39: Grid Electricity | C39: Electricity – purchased from grid [kWh] | D39: Electricity [kWh] | E39: Downer | F39: 2026-01-01 | H39: Jun 26 | I39: 199.9 | J39: 100 | K39: 0 | L39: 78 - Electricity - 25-26 - Victoria | M39: 0.78 | N39: 0.1559 | P39: 0.1559 | Q39: =IF(M39="","",I39*M39/1000) -> 0.155922 | R39: =IF(Q39="","",Q39-N(P39)) -> 2.2e-05 | S39: =IF(L39="","",IF(ISNUMBER(SEARCH("25-26",L39)),"25-26",IF(ISNUMBER(SEARCH("24-25",L39)),"24-25","other"))) -> 25-26 | W39: =IF(AND(R39<>"",ABS(R39)>0.05),"CO2e not kWh x factor",IF(V39="kWh differs from source","Virtual meter not mirroring",IF(AND(D39="Certificates - Location [kWh]",S39="24-25"),"Certificate on 24-25 factor","OK"))) -> OK
A40: Calder Park Light Service Facility | B40: Grid Electricity | C40: Electricity – purchased from grid [kWh] | D40: Electricity [kWh] | E40: Downer | F40: 2026-01-01 | H40: Jul 26 | I40: 206.5623 | J40: 0 | K40: 100 | L40: 78 - Electricity - 25-26 - Victoria | M40: 0.78 | N40: 0.1611 | P40: 0.1611 | Q40: =IF(M40="","",I40*M40/1000) -> 0.16111859 | R40: =IF(Q40="","",Q40-N(P40)) -> 1.8594e-05 | S40: =IF(L40="","",IF(ISNUMBER(SEARCH("25-26",L40)),"25-26",IF(ISNUMBER(SEARCH("24-25",L40)),"24-25","other"))) -> 25-26 | W40: =IF(AND(R40<>"",ABS(R40)>0.05),"CO2e not kWh x factor",IF(V40="kWh differs from source","Virtual meter not mirroring",IF(AND(D40="Certificates - Location [kWh]",S40="24-25"),"Certificate on 24-25 factor","OK"))) -> OK
...

Sheet Sites
A1: Location | B1: NMI | C1: Register decision | D1: Contracted retailer | E1: Source account (Jul 26) | F1: Source style | G1: Certificate account | H1: Built? | I1: Factor on certificate | J1: Electricity factor | K1: Jul 26 kWh (source) | L1: Jul 26 location-based (t) | M1: Jul 26 certificate credit (t) | N1: Jul 26 location market-based (t) | O1: Status | P1: Note
A2: Auburn | B2: 4103713125 | C2: Create - virtual certificate account | D2: Origin | E2: 50002617957_4103713125 | F2: Electricity Large Market | G2: 50002617957_4103713125_CERTS | H2: =IF(G2="","n/a",IF(COUNTIFS(Accounts!$B:$B,G2)>0,"Yes","No")) -> Yes | I2: LGCs NSW 24-25 | J2: 77 - Electricity - 25-26 - New South Wales | K2: =IF(E2="","",SUMIFS(Accounts!$I:$I,Accounts!$B:$B,E2,Accounts!$H:$H,"Jul 26",Accounts!$D:$D,"Electricity [kWh]")) -> 283780.3 | L2: =SUMIFS(Accounts!$N:$N,Accounts!$A:$A,A2,Accounts!$H:$H,"Jul 26") -> 198.5798 | M2: =SUMIFS(Accounts!$O:$O,Accounts!$A:$A,A2,Accounts!$H:$H,"Jul 26") -> -204.7855 | N2: =L2+M2 -> -6.2057 | O2: Factor vintage | P2: Mirrors source. On the 24-25 LGC factor, so it over-offsets by ~3% (-5.7 t in July).
A3: Auburn | B3: 4103711576 | C3: Create - virtual certificate account | D3: Origin | E3: 50002617965_4103711576 | F3: Electricity Large Market | G3: 50002617965_4103711576_CERTS | H3: =IF(G3="","n/a",IF(COUNTIFS(Accounts!$B:$B,G3)>0,"Yes","No")) -> Yes | I3: LGCs NSW 24-25 | J3: 77 - Electricity - 25-26 - New South Wales | K3: =IF(E3="","",SUMIFS(Accounts!$I:$I,Accounts!$B:$B,E3,Accounts!$H:$H,"Jul 26",Accounts!$D:$D,"Electricity [kWh]")) -> 26500.7 | L3: =SUMIFS(Accounts!$N:$N,Accounts!$A:$A,A3,Accounts!$H:$H,"Jul 26") -> 198.5798 | M3: =SUMIFS(Accounts!$O:$O,Accounts!$A:$A,A3,Accounts!$H:$H,"Jul 26") -> -204.7855 | N3: =L3+M3 -> -6.2057 | O3: Factor vintage | P3: Mirrors source. Same factor vintage issue (-0.5 t in July). Usage fell from 204,615 kWh in Mar to 3,263 in May and is 26,500 in Jul.
A4: Maryborough | B4: QGGG000010 | C4: Create - virtual certificate account | D4: Engie | E4: 900018200_QGGG000010 | F4: Electricity Small Market | G4: 900018200_QGGG000010_CERTS | H4: =IF(G4="","n/a",IF(COUNTIFS(Accounts!$B:$B,G4)>0,"Yes","No")) -> Yes | I4: LGCs QLD 24-25 | J4: 79 - Electricity - 25-26 - Queensland | K4: =IF(E4="","",SUMIFS(Accounts!$I:$I,Accounts!$B:$B,E4,Accounts!$H:$H,"Jul 26",Accounts!$D:$D,"Electricity [kWh]")) -> 277212.1 | L4: =SUMIFS(Accounts!$N:$N,Accounts!$A:$A,A4,Accounts!$H:$H,"Jul 26") -> 93.6872 | M4: =SUMIFS(Accounts!$O:$O,Accounts!$A:$A,A4,Accounts!$H:$H,"Jul 26") -> -196.8206 | N4: =L4+M4 -> -103.1334 | O4: Over-credited | P4: Mirrors the gross NMI figure. The CQMS foundry deduction (-141,380 kWh) sits at the same location, so the site nets to about -103 t. Gross vs net is the open Category Management question. Also on the 24-25 factor (-0.71 vs 0.67).
A5: Maryborough | B5: QGGG000320 | C5: Hold - no open account on the NMI | D5: Engie | H5: =IF(G5="","n/a",IF(COUNTIFS(Accounts!$B:$B,G5)>0,"Yes","No")) -> n/a | J5: 79 - Electricity - 25-26 - Queensland | K5: =IF(E5="","",SUMIFS(Accounts!$I:$I,Accounts!$B:$B,E5,Accounts!$H:$H,"Jul 26",Accounts!$D:$D,"Electricity [kWh]")) | L5: =SUMIFS(Accounts!$N:$N,Accounts!$A:$A,A5,Accounts!$H:$H,"Jul 26") -> 93.6872 | M5: =SUMIFS(Accounts!$O:$O,Accounts!$A:$A,A5,Accounts!$H:$H,"Jul 26") -> -196.8206 | N5: =L5+M5 -> -103.1334 | O5: Nothing recording | P5: CS Energy account 1003082 closed 30 Jun 26, no Engie account yet. Meter reads 12,413 kWh in July and 10,262 in August - uncounted.
A6: Torbanlea - QTMP | B6: 3053253239 | C6: Exclude - named site (QTMP) | D6: Engie | E6: 900018201_3053253239 | F6: Electricity Small Market | H6: =IF(G6="","n/a",IF(COUNTIFS(Accounts!$B:$B,G6)>0,"Yes","No")) -> n/a | J6: 79 - Electricity - 25-26 - Queensland | K6: =IF(E6="","",SUMIFS(Accounts!$I:$I,Accounts!$B:$B,E6,Accounts!$H:$H,"Jul 26",Accounts!$D:$D,"Electricity [kWh]")) -> 248501.6 | L6: =SUMIFS(Accounts!$N:$N,Accounts!$A:$A,A6,Accounts!$H:$H,"Jul 26") -> 166.4961 | M6: =SUMIFS(Accounts!$O:$O,Accounts!$A:$A,A6,Accounts!$H:$H,"Jul 26") -> 0 | N6: =L6+M6 -> 166.4961 | O6: Confirm bill | P6: No certificate account is correct for a named exclusion. July's Engie bill is 248,502 kWh against 164,454 in June and 170,055 in August - confirm the bill period. Old CS Energy account 1003571 closed 30 Jun 26 in the 5 Sep extract.
A7: Cardiff - Rail | B7: ZZZZ001261 | C7: Not in the renewal register | D7: CleanPeak | E7: 700000536_ZZZZ001261 | F7: Electricity Small Market | H7: =IF(G7="","n/a",IF(COUNTIFS(Accounts!$B:$B,G7)>0,"Yes","No")) -> n/a | J7: 77 - Electricity - 25-26 - New South Wales | K7: =IF(E7="","",SUMIFS(Accounts!$I:$I,Accounts!$B:$B,E7,Accounts!$H:$H,"Jul 26",Accounts!$D:$D,"Electricity [kWh]")) -> 258866.97 | L7: =SUMIFS(Accounts!$N:$N,Accounts!$A:$A,A7,Accounts!$H:$H,"Jul 26") -> 98.7423 | M7: =SUMIFS(Accounts!$O:$O,Accounts!$A:$A,A7,Accounts!$H:$H,"Jul 26") -> 0 | N7: =L7+M7 -> 98.7423 | O7: OK | P7: Small market on CleanPeak, tenant deduction of -104,582 kWh in July. Location-based only; nothing to check for certificates.
A8: HCMT - East Pakenham Depot | C8: Not in the renewal register | E8: 68_Electricity – purchased from grid | F8: Purchased from grid | G8: HCMT 100% Renewable Deduction | H8: =IF(G8="","n/a",IF(COUNTIFS(Accounts!$B:$B,G8)>0,"Yes","No")) -> Yes | I8: LGCs Victoria 25-26 | J8: 78 - Electricity - 25-26 - Victoria | K8: =IF(E8="","",SUMIFS(Accounts!$I:$I,Accounts!$B:$B,E8,Accounts!$H:$H,"Jul 26",Accounts!$D:$D,"Electricity [kWh]")) -> 219172 | L8: =SUMIFS(Accounts!$N:$N,Accounts!$A:$A,A8,Accounts!$H:$H,"Jul 26") -> 170.9542 | M8: =SUMIFS(Accounts!$O:$O,Accounts!$A:$A,A8,Accounts!$H:$H,"Jul 26") -> -170.9542 | N8: =L8+M8 -> 0 | O8: OK | P8: Deduction mirrors the grid account and the factor vintages match, so the site nets to zero every month. Correct.
A9: Calder Park Light Service Facility | C9: Not in the renewal register | E9: Grid Electricity | F9: Purchased from grid | G9: Calder Park 100% Renewable Electricity | H9: =IF(G9="","n/a",IF(COUNTIFS(Accounts!$B:$B,G9)>0,"Yes","No")) -> Yes | I9: LGCs Victoria 25-26 | J9: 78 - Electricity - 25-26 - Victoria | K9: =IF(E9="","",SUMIFS(Accounts!$I:$I,Accounts!$B:$B,E9,Accounts!$H:$H,"Jul 26",Accounts!$D:$D,"Electricity [kWh]")) -> 206.5623 | L9: =SUMIFS(Accounts!$N:$N,Accounts!$A:$A,A9,Accounts!$H:$H,"Jul 26") -> 0.1611 | M9: =SUMIFS(Accounts!$O:$O,Accounts!$A:$A,A9,Accounts!$H:$H,"Jul 26") -> -0.1611 | N9: =L9+M9 -> 0 | O9: OK | P9: As HCMT. Nets to zero. Correct.
A11: Rows 2-6 are the five RTS rows in the FY26-28 renewal site register; rows 7-9 are the other RTS locations with electricity in the export. Yellow = hand-maintained status. Everything numeric is a formula over the Accounts tab.

Sheet Issues
A1: # | B1: Location | C1: Issue | D1: Effect on July (tCO2e) | E1: Action | F1: Owner | G1: Status | H1: Notes
A2: 1 | B2: Dashboard | C2: July 928 t does not reconcile to the market-based electricity in the 6 Sep export (166 t). Best fit is a refresh taken while the CS Energy accounts at Maryborough and Torbanlea were still accruing July alongside the Engie actuals, before the certificate accounts were linked. | D2: 282 | E2: Refresh the dashboard from current data. If July stays high, pull RTS scope 1 (gas, fuel) for July - it is not in this repo. | G2: Open
A3: 2 | B3: Maryborough | C3: Certificate account 900018200_QGGG000010_CERTS copies the gross NMI figure while the CQMS foundry deduction nets ~141,000 kWh off the location, so Maryborough reports about -103 t. | D3: -95 | E3: Category Management to confirm whether certificates are bought for the gross NMI or Downer's net share. If net, repoint the virtual meter or add a matching deduction on the certificate side. | G3: Open
A4: 3 | B4: Auburn / Maryborough | C4: Certificate accounts sit on LGCs NSW 24-25 (-0.66) and LGCs QLD 24-25 (-0.71) against electricity on 25-26 (0.64, 0.67). | D4: -17 | E4: Add or map the 25-26 LGC factors for NSW and QLD (prompt 3 in the guide) and move the three accounts onto them. | G4: Open
A5: 4 | B5: Maryborough | C5: QGGG000320: CS Energy account closed 30 Jun 26, no Engie account yet, so nothing is recording July or August. Meter shows 12,413 and 10,262 kWh. | D5: -8 | E5: Chase the Engie account for QGGG000320 through the connector, then allocate it to Maryborough. | G5: Open
A6: 5 | B6: Torbanlea - QTMP | C6: Engie's first bill on 900018201_3053253239 is 248,502 kWh for July, 51% above June and 46% above August. | D6: 56 | E6: Confirm the July bill period with Engie or Category Management; if it covers late June, split it. | G6: Open
A7: 6 | B7: Auburn | C7: Sub-meter DWR_MSB-5-LATHE reads 601,436 kWh in July (3 kWh in June), about 385 t at the NSW factor. Meters carry no CO2e in the account export, but this matches the dashboard's June-to-July increase almost exactly. | D7: 0 | E7: Check whether the RTS dashboard sums meters as well as accounts. Either way the sub-meter reading is a fault and should be raised with the Watt Watcher / metering provider. | G7: Open
A8: 7 | B8: Auburn | C8: NEMMCO meter 4103713125 reads twice the Origin account every month (567,561 vs 283,780 kWh in July) - the Wingfield pattern. | D8: 0 | E8: Note only; no effect on account-based emissions. Raise with metering if the meter is ever used for reporting. | G8: Open
A10: Yellow = fill in as each item moves. Status is a list.
